#VRML_SIM R2023b utf8

EXTERNPROTO "https://raw.githubusercontent.com/cyberbotics/webots/R2023b/projects/objects/backgrounds/protos/TexturedBackground.proto"
EXTERNPROTO "https://raw.githubusercontent.com/cyberbotics/webots/R2023b/projects/objects/backgrounds/protos/TexturedBackgroundLight.proto"
EXTERNPROTO "https://raw.githubusercontent.com/cyberbotics/webots/R2023b/projects/objects/floors/protos/RectangleArena.proto"
EXTERNPROTO "https://raw.githubusercontent.com/cyberbotics/webots/R2023b/projects/appearances/protos/FlexibleAluminiumDuct.proto"
EXTERNPROTO "https://raw.githubusercontent.com/cyberbotics/webots/R2023b/projects/objects/traffic/protos/TrafficCone.proto"

WorldInfo {
}
Viewpoint {
  orientation -0.2662047545191887 -0.15970484657859751 0.9505942302847653 4.198989206645395
  position 3.9972306136288376 0.4673931048191809 0.22150190226003622
  exposure 0.3
  follow "AlphieBeta"
  followType "None"
  followSmoothness 1
  ambientOcclusionRadius 0
  bloomThreshold 5
}
TexturedBackground {
  texture "dusk"
  luminosity 8
}
TexturedBackgroundLight {
}
RectangleArena {
  translation 0 1e-13 -8.32268e-14
  rotation 1 0 0 4.07987e-06
  floorSize 10 10
  floorTileSize 2 2
}
Solid {
  translation 2 2 0.05
  children [
    Shape {
      appearance PBRAppearance {
        baseColor 1 0 0
      }
      geometry Box {
        size 0.1 0.1 0.1
      }
    }
  ]
  name "CIBLE"
}
DEF Alphie Robot {
  translation 3.85 0.180031 -4.37081e-05
  rotation 0.06719508621691139 -0.5522158867292101 -0.8309888295471691 0.000195699
  children [
    Group {
    }
    DEF BODY Group {
      children [
        DEF LEFT_TRACK Pose {
          translation 0 0.0295 0.014
          rotation 1 0 0 -1.57
          children [
            DEF TRACK Group {
              children [
                Pose {
                  translation -0.049 0 0
                  children [
                    DEF TRACK_EXTRUSION Shape {
                      appearance DEF BLACK PBRAppearance {
                        baseColor 0 0 0
                        roughness 0.7
                        metalness 0
                      }
                      geometry IndexedFaceSet {
                        coord Coordinate {
                          point [
                            0 0.014 0
                            -0.007 0.01212 0
                            -0.01212 0.007 0
                            -0.014 0 0
                            -0.01212 -0.007 0
                            -0.007 -0.01212 0
                            0 -0.014 0
                            0 0.014 0
                            0 0.014 0.0198
                            -0.007 0.01212 0.0198
                            -0.01212 0.007 0.0198
                            -0.014 0 0.0198
                            -0.01212 -0.007 0.0198
                            -0.007 -0.01212 0.0198
                            0 -0.014 0.0198
                            0 0.014 0.0198
                          ]
                        }
                        coordIndex [
                          7, 6, 5, 4, 3, 2, 1, 0, -1, 8, 9, 10, 11, 12, 13, 14, 15, -1, 0, 1, 9, 8, -1, 1, 2, 10, 9, -1, 2, 3, 11, 10, -1, 3, 4, 12, 11, -1, 4, 5, 13, 12, -1, 5, 6, 14, 13, -1, 6, 7, 15, 14, -1
                        ]
                      }
                    }
                  ]
                }
                Pose {
                  translation 0.049 0 0
                  rotation 0 0 1 3.14
                  children [
                    DEF TRACK_EXTRUSION Shape {
                      appearance USE BLACK
                      geometry IndexedFaceSet {
                        coord Coordinate {
                          point [
                            0 0.014 0
                            -0.007 0.01212 0
                            -0.01212 0.007 0
                            -0.014 0 0
                            -0.01212 -0.007 0
                            -0.007 -0.01212 0
                            0 -0.014 0
                            0 0.014 0
                            0 0.014 0.0198
                            -0.007 0.01212 0.0198
                            -0.01212 0.007 0.0198
                            -0.014 0 0.0198
                            -0.01212 -0.007 0.0198
                            -0.007 -0.01212 0.0198
                            0 -0.014 0.0198
                            0 0.014 0.0198
                          ]
                        }
                        coordIndex [
                          7, 6, 5, 4, 3, 2, 1, 0, -1, 8, 9, 10, 11, 12, 13, 14, 15, -1, 0, 1, 9, 8, -1, 1, 2, 10, 9, -1, 2, 3, 11, 10, -1, 3, 4, 12, 11, -1, 4, 5, 13, 12, -1, 5, 6, 14, 13, -1, 6, 7, 15, 14, -1
                        ]
                      }
                    }
                  ]
                }
                Pose {
                  translation 0.049 0 0.0101
                  children [
                    DEF TRACK_WHEEL Shape {
                      appearance DEF GRAY PBRAppearance {
                        roughness 0.2
                      }
                      geometry Cylinder {
                        height 0.0205
                        radius 0.011
                      }
                    }
                  ]
                }
                Pose {
                  translation -0.049 0 0.0101
                  children [
                    USE TRACK_WHEEL
                  ]
                }
                Pose {
                  translation 0 -0.0125 0.0099
                  children [
                    DEF TRACK_BOX Shape {
                      appearance USE BLACK
                      geometry Box {
                        size 0.098 0.003 0.0198
                      }
                    }
                  ]
                }
                Pose {
                  translation 0 0.0125 0.0099
                  children [
                    USE TRACK_BOX
                  ]
                }
              ]
            }
          ]
        }
        DEF RIGHT_TRACK Pose {
          translation 0 -0.0295 0.014
          rotation 1 0 0 1.57
          children [
            USE TRACK
          ]
        }
        DEF BASE Pose {
          translation 0 0 0.014
          children [
            Pose {
              translation -0.056 -5.91374e-08 0.02
              rotation 0 0 1 -1.5707953071795862
              children [
                Shape {
                  appearance PBRAppearance {
                    baseColor 0 0 0
                    roughness 1
                    metalness 0
                  }
                  geometry Box {
                    size 0.055 0.001 0.021
                  }
                }
              ]
              translationStep 0.001
            }
            Pose {
              translation -0.0182 0.026 0.014
              children [
                Shape {
                  appearance PBRAppearance {
                    baseColor 0 0 0
                    roughness 1
                    metalness 0
                  }
                  geometry Box {
                    size 0.075 0.001 0.034
                  }
                }
              ]
              translationStep 0.0001
            }
            Pose {
              translation -0.019 -0.0266 0.0145
              children [
                Shape {
                  appearance PBRAppearance {
                    baseColor 0 0 0
                    roughness 1
                    metalness 0
                  }
                  geometry Box {
                    size 0.075 0.001 0.034
                  }
                }
              ]
              translationStep 0.0001
            }
            Pose {
              translation -0.0466 -0.016 0.00562
              rotation 1 0 0 1.57
              children [
                DEF WHEEL_AXE Shape {
                  appearance PBRAppearance {
                    baseColor 0.392157 0.392157 0.392157
                    roughness 1
                    metalness 0
                  }
                  geometry Cylinder {
                    height 0.02
                    radius 0.0035
                  }
                }
              ]
              translationStep 0.0001
            }
            Pose {
              translation -0.0466 0.0159912 0.00562
              rotation 1 0 0 1.57
              children [
                USE WHEEL_AXE
              ]
              translationStep 0.001
            }
          ]
        }
        DEF FRONT_SUPPORT Pose {
          translation 0.0754 0 0.021
          children [
            DEF Composant Group {
              children [
                DEF ANTENNEGPS Pose {
                  translation -0.0427 -0.012 0.0118
                  children [
                    Solid {
                      translation 0 0 0.0312
                      children [
                        TrafficCone {
                          scale 0.03
                        }
                      ]
                      name "GPSComposant"
                      translationStep 0.0001
                    }
                    Solid {
                      translation 0 0 0.0314
                      children [
                        Shape {
                          appearance FlexibleAluminiumDuct {
                          }
                          geometry Cylinder {
                            height 0.0005
                            radius 0.02
                          }
                        }
                      ]
                      name "plaqueMetal"
                      translationStep 0.0001
                    }
                    Solid {
                      translation 0 0 0.0168
                      children [
                        Shape {
                          appearance PBRAppearance {
                            baseColor 1 0 0
                            roughness 1
                          }
                          geometry Cylinder {
                            height 0.03
                            radius 0.006
                          }
                        }
                      ]
                      name "colonne"
                      translationStep 0.0001
                    }
                    Shape {
                      appearance PBRAppearance {
                        baseColor 1 0 0
                        roughness 1
                      }
                      geometry Box {
                        size 0.026 0.023 0.003
                      }
                    }
                  ]
                  translationStep 0.0001
                }
                DEF CARTEMOTEUR Pose {
                  translation -0.1059 0.0112 0.0276
                  children [
                    Shape {
                      appearance PBRAppearance {
                        baseColorMap ImageTexture {
                          url [
                            "../pictures/carte_moteur.png"
                          ]
                        }
                        roughnessMap ImageTexture {
                          url [
                            ""
                          ]
                        }
                        metalness 0
                        metalnessMap ImageTexture {
                          url [
                            "https://raw.githubusercontent.com/cyberbotics/webots/R2023b/projects/robots/surveyor/protos/textures/surveyor_serial_metalness.jpg"
                          ]
                        }
                        normalMap ImageTexture {
                          url [
                            "https://raw.githubusercontent.com/cyberbotics/webots/R2023b/projects/robots/surveyor/protos/textures/surveyor_serial_normal.jpg"
                          ]
                        }
                      }
                      geometry IndexedFaceSet {
                        coord Coordinate {
                          point [
                            0.017 -0.015 0.0031
                            -0.019 -0.015 0.0031
                            -0.019 0.015 0.0031
                            0.017 0.0145 0.0031
                          ]
                        }
                        texCoord TextureCoordinate {
                          point [
                            0 0
                            1 0
                            1 1
                            0 1
                          ]
                        }
                        coordIndex [
                          0, 3, 2, 1, -1
                        ]
                        texCoordIndex [
                          0, 1, 2, 3, -1
                        ]
                      }
                    }
                    Shape {
                      appearance USE BLACK
                      geometry Box {
                        size 0.031 0.028 0.006
                      }
                    }
                  ]
                  translationStep 0.0001
                }
                DEF BREADBOARD Pose {
                  translation -0.0718 0.0177 0.0274
                  children [
                    Shape {
                      appearance PBRAppearance {
                        baseColorMap ImageTexture {
                          url [
                            "../pictures/breadboard.jpg"
                          ]
                        }
                        roughnessMap ImageTexture {
                          url [
                            "https://raw.githubusercontent.com/cyberbotics/webots/R2023b/projects/robots/surveyor/protos/textures/surveyor_serial_roughness.jpg"
                          ]
                        }
                        metalness 0
                        metalnessMap ImageTexture {
                          url [
                            "https://raw.githubusercontent.com/cyberbotics/webots/R2023b/projects/robots/surveyor/protos/textures/surveyor_serial_metalness.jpg"
                          ]
                        }
                        normalMap ImageTexture {
                          url [
                            "https://raw.githubusercontent.com/cyberbotics/webots/R2023b/projects/robots/surveyor/protos/textures/surveyor_serial_normal.jpg"
                          ]
                        }
                      }
                      geometry IndexedFaceSet {
                        coord Coordinate {
                          point [
                            0.0105 0.0075 0.00251
                            0.0105 -0.0075 0.00251
                            -0.0105 -0.0072 0.00251
                            -0.0105 0.0072 0.00251
                          ]
                        }
                        texCoord TextureCoordinate {
                          point [
                            0 0
                            1 0
                            1 1
                            0 1
                          ]
                        }
                        coordIndex [
                          0, 3, 2, 1, -1
                        ]
                        texCoordIndex [
                          0, 1, 2, 3, -1
                        ]
                      }
                    }
                    Shape {
                      appearance PBRAppearance {
                        baseColor 0.870588 0.870588 0.870588
                        roughness 1
                        metalness 0
                      }
                      geometry Box {
                        size 0.021 0.015 0.005
                      }
                    }
                  ]
                  translationStep 0.0001
                }
                DEF RADIO Pose {
                  translation -0.0344 0.0118 0.013
                  rotation 0 0 1 3.14159
                  children [
                    Shape {
                      appearance PBRAppearance {
                        baseColorMap ImageTexture {
                          url [
                            "../pictures/ModuleRadio.png"
                          ]
                        }
                        roughnessMap ImageTexture {
                          url [
                            "https://raw.githubusercontent.com/cyberbotics/webots/R2023b/projects/robots/surveyor/protos/textures/surveyor_serial_roughness.jpg"
                          ]
                        }
                        metalnessMap ImageTexture {
                          url [
                            "https://raw.githubusercontent.com/cyberbotics/webots/R2023b/projects/robots/surveyor/protos/textures/surveyor_serial_metalness.jpg"
                          ]
                        }
                        normalMap ImageTexture {
                          url [
                            "https://raw.githubusercontent.com/cyberbotics/webots/R2023b/projects/robots/surveyor/protos/textures/surveyor_serial_normal.jpg"
                          ]
                        }
                      }
                      geometry IndexedFaceSet {
                        coord Coordinate {
                          point [
                            0.01 -0.0035 0.0016
                            -0.01 -0.0035 0.0016
                            -0.01 0.0035 0.0016
                            0.01 0.0035 0.0016
                          ]
                        }
                        texCoord TextureCoordinate {
                          point [
                            0 0
                            1 0
                            1 1
                            0 1
                          ]
                        }
                        coordIndex [
                          0, 3, 2, 1, -1
                        ]
                        texCoordIndex [
                          0, 1, 2, 3, -1
                        ]
                      }
                    }
                    Shape {
                      appearance USE BLACK
                      geometry Box {
                        size 0.02 0.007 0.003
                      }
                    }
                  ]
                  translationStep 0.0001
                }
                DEF ARDUINOR4 Pose {
                  translation -0.1044 -0.0158 0.0264
                  children [
                    Shape {
                      appearance PBRAppearance {
                        baseColorMap ImageTexture {
                          url [
                            "../pictures/UnoR4Wifi.png"
                          ]
                          filtering 3
                        }
                        roughnessMap ImageTexture {
                          url [
                            "https://raw.githubusercontent.com/cyberbotics/webots/R2023b/projects/robots/surveyor/protos/textures/surveyor_serial_roughness.jpg"
                          ]
                        }
                        metalness 0
                        metalnessMap ImageTexture {
                          url [
                            "https://raw.githubusercontent.com/cyberbotics/webots/R2023b/projects/robots/surveyor/protos/textures/surveyor_serial_metalness.jpg"
                          ]
                        }
                        normalMap ImageTexture {
                          url [
                            "https://raw.githubusercontent.com/cyberbotics/webots/R2023b/projects/robots/surveyor/protos/textures/surveyor_serial_normal.jpg"
                          ]
                        }
                      }
                      geometry IndexedFaceSet {
                        coord Coordinate {
                          point [
                            -0.0184 -0.01 0.00151
                            -0.0183 0.01 0.00151
                            0.0185 0.01 0.00151
                            0.0185 -0.01 0.00151
                          ]
                        }
                        texCoord TextureCoordinate {
                          point [
                            0 0
                            1 0
                            1 1
                            0 1
                          ]
                        }
                        coordIndex [
                          0, 3, 2, 1, -1
                        ]
                        texCoordIndex [
                          0, 1, 2, 3, -1
                        ]
                      }
                    }
                    Shape {
                      appearance USE BLACK
                      geometry Box {
                        size 0.037 0.02 0.003
                      }
                    }
                  ]
                }
              ]
            }
            DEF SUPPORT Group {
              children [
                Pose {
                  translation -0.0364 0 -0.004
                  children [
                    Shape {
                      appearance DEF BlackRobotAlphie PBRAppearance {
                        baseColor 0 0 0
                        roughness 1
                        metalness 0
                        name ""
                      }
                      geometry Box {
                        size 0.04 0.0525 0.0011
                      }
                    }
                  ]
                  translationStep 0.001
                }
                Pose {
                  translation -0.0433 0 0.0102
                  children [
                    Shape {
                      appearance DEF BlackRobotAlphie PBRAppearance {
                        baseColor 0 0 0
                        roughness 1
                        metalness 0
                        name ""
                      }
                      geometry Box {
                        size 0.03 0.0525 0.0011
                      }
                    }
                  ]
                  translationStep 0.0001
                }
                Shape {
                  appearance PBRAppearance {
                    baseColor 0.85098 0.85098 0.85098
                    baseColorMap ImageTexture {
                      url [
                        "../pictures/FrontAlphie.png"
                      ]
                      repeatS FALSE
                      repeatT FALSE
                    }
                    roughness 1
                    roughnessMap ImageTexture {
                      url [
                        "https://raw.githubusercontent.com/cyberbotics/webots/R2023b/projects/robots/surveyor/protos/textures/surveyor_top_roughness.jpg"
                      ]
                    }
                    metalness 0
                    metalnessMap ImageTexture {
                      url [
                        "https://raw.githubusercontent.com/cyberbotics/webots/R2023b/projects/robots/surveyor/protos/textures/surveyor_top_metalness.jpg"
                      ]
                    }
                    normalMap ImageTexture {
                      url [
                        "https://raw.githubusercontent.com/cyberbotics/webots/R2023b/projects/robots/surveyor/protos/textures/surveyor_top_normal.jpg"
                      ]
                    }
                  }
                  geometry IndexedFaceSet {
                    coord Coordinate {
                      point [
                        -0.059 0.026 0.011
                        -0.028 0.026 0.011
                        -0.028 -0.026 0.011
                        -0.059 -0.026 0.011
                      ]
                    }
                    texCoord TextureCoordinate {
                      point [
                        0 0
                        1 0
                        1 1
                        0 1
                      ]
                    }
                    coordIndex [
                      0, 3, 2, 1, -1
                    ]
                    texCoordIndex [
                      0, 1, 2, 3, -1
                    ]
                  }
                }
                Pose {
                  translation -0.0227073 3.05188e-07 0.00330141
                  rotation -0.6848107156457631 0.6848157156436869 -0.2491218965570118 2.65328
                  children [
                    Shape {
                      appearance USE BlackRobotAlphie
                      geometry Box {
                        size 0.0525 0.0012 0.0185
                      }
                    }
                  ]
                  translationStep 0.0001
                }
              ]
            }
          ]
        }
        DEF TOP_PLATE Group {
          children [
            Pose {
              translation -0.0186 0 0.0449
              children [
                Shape {
                  appearance PBRAppearance {
                    baseColor 0 0 0
                    roughness 1
                    metalness 0
                  }
                  geometry Box {
                    size 0.076 0.053 0.0015
                  }
                }
              ]
              translationStep 0.001
            }
            DEF TOP Pose {
              translation -0.006 -6.36861e-08 0.0477
              rotation 0 0 1 3.14159
              children [
                GPS {
                  rotation 0 0 1 3.14159
                }
                Compass {
                  rotation 0 0 1 3.14159
                }
                Shape {
                  appearance PBRAppearance {
                    baseColorMap ImageTexture {
                      url [
                        "../pictures/TopAlphie.png"
                      ]
                      repeatS FALSE
                      repeatT FALSE
                    }
                    roughness 1
                    roughnessMap ImageTexture {
                      url [
                        "https://raw.githubusercontent.com/cyberbotics/webots/R2023b/projects/robots/surveyor/protos/textures/surveyor_top_roughness.jpg"
                      ]
                    }
                    metalness 0
                    metalnessMap ImageTexture {
                      url [
                        "https://raw.githubusercontent.com/cyberbotics/webots/R2023b/projects/robots/surveyor/protos/textures/surveyor_top_metalness.jpg"
                      ]
                    }
                    normalMap ImageTexture {
                      url [
                        "https://raw.githubusercontent.com/cyberbotics/webots/R2023b/projects/robots/surveyor/protos/textures/surveyor_top_normal.jpg"
                      ]
                    }
                  }
                  geometry IndexedFaceSet {
                    coord Coordinate {
                      point [
                        0.05 -0.027 -0.002
                        -0.026 -0.027 -0.002
                        -0.026 0.027 -0.002
                        0.05 0.027 -0.002
                      ]
                    }
                    texCoord TextureCoordinate {
                      point [
                        0 0
                        1 0
                        1 1
                        0 1
                      ]
                    }
                    coordIndex [
                      0, 3, 2, 1, -1
                    ]
                    texCoordIndex [
                      0, 1, 2, 3, -1
                    ]
                  }
                }
              ]
              translationStep 0.001
            }
          ]
        }
        DEF BATTERIES Group {
          children [
            Pose {
              translation -0.0220079 -5.51926e-08 0.0270237
              rotation 0.577656895078166 -0.5771968951617173 0.5771968951617173 2.09394
              children [
                DEF BATTERY Shape {
                  appearance DEF BlackRobot PBRAppearance {
                    baseColor 0.360784 0.360784 0.360784
                    roughness 1
                    metalness 0
                  }
                  geometry Box {
                    size 0.015 0.02 0.05
                  }
                }
              ]
            }
          ]
        }
      ]
    }
    DEF ANTENNA_EMITTER Emitter {
      translation 0.0451 0.0118 0.037
      children [
        Pose {
          translation 0 0 -0.008
          children [
            Shape {
              appearance USE BLACK
              geometry Cylinder {
                height 0.019
                radius 0.0006
              }
            }
          ]
        }
        Pose {
          children [
            Shape {
              appearance USE BLACK
              geometry Cylinder {
                height 0.007
                radius 0.0015
              }
            }
          ]
        }
      ]
      translationStep 0.0001
    }
    DEF ANTENNA_RECEIVER Receiver {
      translation 0.0451 0.0118 0.037
    }
    DEF FIRST_LEFT_WHEEL HingeJoint {
      jointParameters HingeJointParameters {
        position -737.196855775293
        axis 0 -1 0
        anchor 0.049 0.0394 0.014
      }
      device [
        RotationalMotor {
          name "wheel_motor00"
          maxVelocity 50
        }
        PositionSensor {
          name "wheel_sensor00"
        }
      ]
      endPoint Solid {
        translation 0.049 0.0394 0.014
        rotation 0 -1 0 4.2190104718982155
        name "first left wheel"
        contactMaterial "wheel"
        boundingObject DEF BOUNDING_WHEEL Pose {
          rotation 1 0 0 -1.57
          children [
            Cylinder {
              height 0.0198
              radius 0.014
            }
          ]
        }
        physics DEF PHYSICS_FRONT_WHEEL Physics {
          density -1
          mass 0.005
        }
      }
    }
    DEF SECOND_LEFT_WHEEL HingeJoint {
      jointParameters HingeJointParameters {
        position 1211.638548435351
        axis 0 -1 0
        anchor 0.0245 0.0394 0.014
      }
      device [
        RotationalMotor {
          name "wheel_motor01"
          maxVelocity 50
        }
        PositionSensor {
          name "wheel_sensor01"
        }
      ]
      endPoint Solid {
        translation 0.0245 0.0394 0.014
        rotation 0 -1 0 5.266969456870309
        name "second left wheel"
        contactMaterial "wheel"
        boundingObject USE BOUNDING_WHEEL
        physics USE PHYSICS_FRONT_WHEEL
      }
    }
    DEF THIRD_LEFT_WHEEL HingeJoint {
      jointParameters HingeJointParameters {
        position -710.1582623977923
        axis 0 -1 0
        anchor 0 0.0394 0.014
      }
      device [
        RotationalMotor {
          name "wheel_motor02"
          maxVelocity 50
        }
        PositionSensor {
          name "wheel_sensor02"
        }
      ]
      endPoint Solid {
        translation 0 0.0394 0.014
        rotation 0 -1 0 6.12486262068053
        name "third left wheel"
        contactMaterial "center_wheel"
        boundingObject USE BOUNDING_WHEEL
        physics DEF PHYSICS_CENTER_WHEEL Physics {
          density -1
          mass 0.005
        }
      }
    }
    DEF FOURTH_LEFT_WHEEL HingeJoint {
      jointParameters HingeJointParameters {
        position -710.1582634140583
        axis 0 -1 0
        anchor -0.0245 0.0394 0.014
      }
      device [
        RotationalMotor {
          name "wheel_motor03"
          maxVelocity 50
        }
        PositionSensor {
          name "wheel_sensor03"
        }
      ]
      endPoint Solid {
        translation -0.0245 0.0394 0.014
        rotation 0 -1 0 6.124861604414561
        name "fourth left wheel"
        contactMaterial "wheel"
        boundingObject USE BOUNDING_WHEEL
        physics USE PHYSICS_FRONT_WHEEL
      }
    }
    DEF LAST_LEFT_WHEEL HingeJoint {
      jointParameters HingeJointParameters {
        position -710.1582470482592
        axis 0 -1 0
        anchor -0.049 0.0394 0.014
      }
      device [
        RotationalMotor {
          name "wheel_motor04"
          maxVelocity 50
        }
        PositionSensor {
          name "wheel_sensor04"
        }
      ]
      endPoint Solid {
        translation -0.049 0.0394 0.014
        rotation 0 -0.9999999999999999 0 6.124877970213632
        name "last left wheel"
        contactMaterial "wheel"
        boundingObject USE BOUNDING_WHEEL
        physics USE PHYSICS_FRONT_WHEEL
      }
    }
    DEF FIRST_RIGHT_WHEEL HingeJoint {
      jointParameters HingeJointParameters {
        position -273.5157538837309
        axis 0 -1 0
        anchor 0.049 -0.0394 0.014
      }
      device [
        RotationalMotor {
          name "wheel_motor05"
          maxVelocity 50
        }
        PositionSensor {
          name "wheel_sensor05"
        }
      ]
      endPoint Solid {
        translation 0.049 -0.0394 0.014
        rotation 0 -1 0 2.94439963217091
        name "first right wheel"
        contactMaterial "wheel"
        boundingObject USE BOUNDING_WHEEL
        physics USE PHYSICS_FRONT_WHEEL
      }
    }
    DEF SECOND_RIGHT_WHEEL HingeJoint {
      jointParameters HingeJointParameters {
        position -273.51575162235395
        axis 0 -1 0
        anchor 0.0245 -0.0394 0.014
      }
      device [
        RotationalMotor {
          name "wheel_motor06"
          maxVelocity 50
        }
        PositionSensor {
          name "wheel_sensor06"
        }
      ]
      endPoint Solid {
        translation 0.0245 -0.0394 0.014
        rotation 0 -0.9999999999999999 0 2.944401893547859
        name "second right wheel"
        contactMaterial "wheel"
        boundingObject USE BOUNDING_WHEEL
        physics USE PHYSICS_FRONT_WHEEL
      }
    }
    DEF THIRD_RIGHT_WHEEL HingeJoint {
      jointParameters HingeJointParameters {
        position -273.5157546012087
        axis 0 -1 0
        anchor 0 -0.0394 0.014
      }
      device [
        RotationalMotor {
          name "wheel_motor07"
          maxVelocity 50
        }
        PositionSensor {
          name "wheel_sensor07"
        }
      ]
      endPoint Solid {
        translation 0 -0.0394 0.014
        rotation 0 -1 0 2.9443989146931067
        name "third right wheel"
        contactMaterial "center_wheel"
        boundingObject USE BOUNDING_WHEEL
        physics USE PHYSICS_CENTER_WHEEL
      }
    }
    DEF FOURTH_RIGHT_WHEEL HingeJoint {
      jointParameters HingeJointParameters {
        position -273.5157562187423
        axis 0 -1 0
        anchor -0.0245 -0.0394 0.014
      }
      device [
        RotationalMotor {
          name "wheel_motor08"
          maxVelocity 50
        }
        PositionSensor {
          name "wheel_sensor08"
        }
      ]
      endPoint Solid {
        translation -0.0245 -0.0394 0.014
        rotation 0 -1 0 2.944397297159508
        name "forth right wheel"
        contactMaterial "wheel"
        boundingObject USE BOUNDING_WHEEL
        physics USE PHYSICS_FRONT_WHEEL
      }
    }
    DEF LAST_RIGHT_WHEEL HingeJoint {
      jointParameters HingeJointParameters {
        position -273.51574194009385
        axis 0 -1 0
        anchor -0.049 -0.0394 0.014
      }
      device [
        RotationalMotor {
          name "wheel_motor09"
          maxVelocity 50
        }
        PositionSensor {
          name "wheel_sensor09"
        }
      ]
      endPoint Solid {
        translation -0.049 -0.0394 0.014
        rotation 0 -1 0 2.9444115758079583
        name "last right wheel"
        contactMaterial "wheel"
        boundingObject USE BOUNDING_WHEEL
        physics USE PHYSICS_FRONT_WHEEL
      }
    }
  ]
  name "AlphieBeta"
  model "SRV-1"
  boundingObject Group {
    children [
      Pose {
        translation 0 0 0.03
        children [
          Box {
            size 0.114 0.0535 0.045
          }
        ]
      }
      Pose {
        translation -0.0039 0 0.063
        children [
          Box {
            size 0.087 0.08 0.017
          }
        ]
      }
    ]
  }
  physics Physics {
    density -1
    mass 0.324
    centerOfMass [
      -0.005 0 0.028
    ]
    inertiaMatrix [
      0.000267079 0.000473553 0.000418585
      0 -6.02166e-06 0
    ]
  }
  controller "GoToCoordinatePython"
}
