#VRML_SIM R2023b utf8

EXTERNPROTO "https://raw.githubusercontent.com/cyberbotics/webots/R2023b/projects/objects/backgrounds/protos/TexturedBackground.proto"
EXTERNPROTO "https://raw.githubusercontent.com/cyberbotics/webots/R2023b/projects/objects/backgrounds/protos/TexturedBackgroundLight.proto"
EXTERNPROTO "https://raw.githubusercontent.com/cyberbotics/webots/R2023b/projects/objects/floors/protos/RectangleArena.proto"
EXTERNPROTO "https://raw.githubusercontent.com/cyberbotics/webots/R2023b/projects/appearances/protos/FlexibleAluminiumDuct.proto"
EXTERNPROTO "https://raw.githubusercontent.com/cyberbotics/webots/R2023b/projects/objects/traffic/protos/TrafficCone.proto"
EXTERNPROTO "https://raw.githubusercontent.com/cyberbotics/webots/R2023b/projects/appearances/protos/ScuffedPlastic.proto"

WorldInfo {
}
Viewpoint {
  orientation -0.006041232671259505 0.9997931148983349 0.019422433155934664 1.119206485930495
  position -4.463950757230424 -0.7339111805556366 10.41890652921136
  exposure 0.3
  followType "None"
  followSmoothness 1
  ambientOcclusionRadius 0
  bloomThreshold 5
}
TexturedBackground {
  texture "dusk"
  luminosity 8
}
TexturedBackgroundLight {
}
RectangleArena {
  translation 0 1e-13 -8.32268e-14
  rotation 1 0 0 4.07987e-06
  name "Floor"
  floorSize 10 10
  floorTileSize 2 2
}
Solid {
  translation -1 -1 0.05
  children [
    Shape {
      appearance PBRAppearance {
        baseColor 1 0 0
      }
      geometry Box {
        size 0.1 0.1 0.1
      }
    }
  ]
  name "CIBLE"
}
Solid {
  translation 1 -1 0.05
  children [
    Shape {
      appearance PBRAppearance {
        baseColor 1 0 0
      }
      geometry Box {
        size 0.1 0.1 0.1
      }
    }
  ]
  name "CIBLE(1)"
}
Solid {
  translation 1 1 0.05
  children [
    Shape {
      appearance PBRAppearance {
        baseColor 1 0 0
      }
      geometry Box {
        size 0.1 0.1 0.1
      }
    }
  ]
  name "CIBLE(2)"
}
Solid {
  translation -1 1 0.05
  children [
    Shape {
      appearance PBRAppearance {
        baseColor 1 0 0
      }
      geometry Box {
        size 0.1 0.1 0.1
      }
    }
  ]
  name "CIBLE(3)"
}
Solid {
  translation -1 1 0.05
  children [
    Shape {
      appearance PBRAppearance {
        baseColor 1 0 0
      }
      geometry Box {
        size 0.1 0.1 0.1
      }
    }
  ]
  name "CIBLE(4)"
}
Solid {
  translation 1.5 0 0.05
  children [
    Shape {
      appearance PBRAppearance {
        baseColor 0 0.333333 0
      }
      geometry Box {
        size 0.1 0.1 0.1
      }
    }
  ]
  name "CIBLE_CERCLE"
}
Solid {
  translation 0 -1.5 0.05
  children [
    Shape {
      appearance PBRAppearance {
        baseColor 0 0.333333 0
      }
      geometry Box {
        size 0.1 0.1 0.1
      }
    }
  ]
  name "CIBLE_CERCLE(1)"
}
Solid {
  translation 0 1.5 0.05
  children [
    Shape {
      appearance PBRAppearance {
        baseColor 0 0.333333 0
      }
      geometry Box {
        size 0.1 0.1 0.1
      }
    }
  ]
  name "CIBLE_CERCLE(2)"
}
Solid {
  translation -1.5 0 0.05
  children [
    Shape {
      appearance PBRAppearance {
        baseColor 0 0.333333 0
      }
      geometry Box {
        size 0.1 0.1 0.1
      }
    }
  ]
  name "CIBLE_CERCLE(3)"
}
Robot {
  translation 0.1 0 0.1
  rotation 0 1 0 0.523599
  children [
    Solid {
      rotation 0 1 0 3.14159
      children [
        Shape {
          appearance ScuffedPlastic {
            colorOverride 0.32549 0.32549 0.32549
          }
          geometry Box {
            size 0.05 0.1 0.1
          }
        }
      ]
      name "Body"
      translationStep 0.0001
    }
    Solid {
      translation -3.17901e-07 0 0.1198
      rotation 0 1 0 3.14159
      children [
        Shape {
          appearance ScuffedPlastic {
            colorOverride 1 0 0
          }
          geometry Sphere {
            radius 0.02
            subdivision 4
          }
        }
      ]
      name "BouleAntenne"
      translationStep 0.0001
    }
    Solid {
      translation -1.82037e-07 0 0.0686
      rotation 0 1 0 3.14159
      children [
        Shape {
          appearance ScuffedPlastic {
            colorOverride 0.32549 0.32549 0.32549
          }
          geometry Box {
            size 0.01 0.01 0.1
          }
        }
      ]
      name "CorpsAntenne"
      translationStep 0.0001
    }
    Solid {
      translation -0.03 0 3.05886e-08
      rotation 0 1 0 -1.5707953071795862
      children [
        Shape {
          appearance ScuffedPlastic {
            colorOverride 0.666667 0 0
          }
          geometry Cylinder {
            height 0.025
            radius 0.028
            subdivision 37
          }
        }
      ]
      name "button"
    }
    Solid {
      translation 0.0003610583896189154 3.1294249020517957e-07 0.11766353341719235
      rotation -0.07482143831466098 0.9968980350770443 -0.024414340622955513 1.561709941217331e-06
      children [
        Receiver {
        }
        Emitter {
          children [
            DEF RangeEmitter Shape {
              appearance PBRAppearance {
                baseColor 0 0 0
                transparency 1
                roughness 1
                metalness 0
              }
              geometry Sphere {
                subdivision 5
              }
            }
          ]
        }
      ]
      name "Antenne"
      translationStep 0.0001
    }
  ]
  name "Remote"
  controller "MainControllerRemote"
}
Robot {
  translation 0.125 -0.14 0.0700988
  rotation 0 1 0 0.523599
  children [
    Solid {
      rotation 0 1 0 3.14159
      children [
        Shape {
          appearance ScuffedPlastic {
            colorOverride 0.32549 0.32549 0.32549
          }
          geometry Box {
            size 0.05 0.1 0.1
          }
        }
      ]
      name "Body"
      translationStep 0.0001
    }
    Solid {
      translation -3.17901e-07 0 0.1198
      rotation 0 1 0 3.14159
      children [
        Shape {
          appearance ScuffedPlastic {
            colorOverride 0 0 1
          }
          geometry Sphere {
            radius 0.02
            subdivision 4
          }
        }
      ]
      name "BouleAntenne"
      translationStep 0.0001
    }
    Solid {
      translation -1.82037e-07 0 0.0686
      rotation 0 1 0 3.14159
      children [
        Shape {
          appearance ScuffedPlastic {
            colorOverride 0.32549 0.32549 0.32549
          }
          geometry Box {
            size 0.01 0.01 0.1
          }
        }
      ]
      name "CorpsAntenne"
      translationStep 0.0001
    }
    Solid {
      translation -0.03 0 3.05886e-08
      rotation 0 1 0 -1.5707953071795862
      children [
        Shape {
          appearance ScuffedPlastic {
            colorOverride 0 0 1
          }
          geometry Cylinder {
            height 0.025
            radius 0.028
            subdivision 37
          }
        }
      ]
      name "button"
    }
    Solid {
      translation 0.0003610583896189154 3.1294249020517957e-07 0.11766353341719235
      rotation -0.07482143831466098 0.9968980350770443 -0.024414340622955513 1.561709941217331e-06
      children [
        Receiver {
        }
        Emitter {
          children [
            DEF RangeEmitter Shape {
              appearance PBRAppearance {
                baseColor 0 0 0
                transparency 1
                roughness 1
                metalness 0
              }
              geometry Sphere {
                subdivision 5
              }
            }
          ]
        }
      ]
      name "Antenne"
      translationStep 0.0001
    }
  ]
  name "Initialiseur_Liste_Robot"
  controller "MainControllerInitialiseur"
}
Robot {
  translation 1.59886 1.4902 0.009826
  rotation -2.557260591886361e-05 6.183924629609812e-05 0.9999999977609748 1.3718482359039352
  children [
    Group {
    }
    DEF BODY Group {
      children [
        DEF LEFT_TRACK Pose {
          translation 0 0.0295 0.014
          rotation 1 0 0 -1.57
          children [
            DEF TRACK Group {
              children [
                Pose {
                  translation -0.049 0 0
                  children [
                    DEF TRACK_EXTRUSION Shape {
                      appearance DEF BLACK PBRAppearance {
                        baseColor 0 0 0
                        roughness 0.7
                        metalness 0
                      }
                      geometry IndexedFaceSet {
                        coord Coordinate {
                          point [
                            0 0.014 0
                            -0.007 0.01212 0
                            -0.01212 0.007 0
                            -0.014 0 0
                            -0.01212 -0.007 0
                            -0.007 -0.01212 0
                            0 -0.014 0
                            0 0.014 0
                            0 0.014 0.0198
                            -0.007 0.01212 0.0198
                            -0.01212 0.007 0.0198
                            -0.014 0 0.0198
                            -0.01212 -0.007 0.0198
                            -0.007 -0.01212 0.0198
                            0 -0.014 0.0198
                            0 0.014 0.0198
                          ]
                        }
                        coordIndex [
                          7, 6, 5, 4, 3, 2, 1, 0, -1, 8, 9, 10, 11, 12, 13, 14, 15, -1, 0, 1, 9, 8, -1, 1, 2, 10, 9, -1, 2, 3, 11, 10, -1, 3, 4, 12, 11, -1, 4, 5, 13, 12, -1, 5, 6, 14, 13, -1, 6, 7, 15, 14, -1
                        ]
                      }
                    }
                  ]
                }
                Pose {
                  translation 0.049 0 0
                  rotation 0 0 1 3.14
                  children [
                    DEF TRACK_EXTRUSION Shape {
                      appearance USE BLACK
                      geometry IndexedFaceSet {
                        coord Coordinate {
                          point [
                            0 0.014 0
                            -0.007 0.01212 0
                            -0.01212 0.007 0
                            -0.014 0 0
                            -0.01212 -0.007 0
                            -0.007 -0.01212 0
                            0 -0.014 0
                            0 0.014 0
                            0 0.014 0.0198
                            -0.007 0.01212 0.0198
                            -0.01212 0.007 0.0198
                            -0.014 0 0.0198
                            -0.01212 -0.007 0.0198
                            -0.007 -0.01212 0.0198
                            0 -0.014 0.0198
                            0 0.014 0.0198
                          ]
                        }
                        coordIndex [
                          7, 6, 5, 4, 3, 2, 1, 0, -1, 8, 9, 10, 11, 12, 13, 14, 15, -1, 0, 1, 9, 8, -1, 1, 2, 10, 9, -1, 2, 3, 11, 10, -1, 3, 4, 12, 11, -1, 4, 5, 13, 12, -1, 5, 6, 14, 13, -1, 6, 7, 15, 14, -1
                        ]
                      }
                    }
                  ]
                }
                Pose {
                  translation 0.049 0 0.0101
                  children [
                    DEF TRACK_WHEEL Shape {
                      appearance DEF GRAY PBRAppearance {
                        roughness 0.2
                      }
                      geometry Cylinder {
                        height 0.0205
                        radius 0.011
                      }
                    }
                  ]
                }
                Pose {
                  translation -0.049 0 0.0101
                  children [
                    USE TRACK_WHEEL
                  ]
                }
                Pose {
                  translation 0 -0.0125 0.0099
                  children [
                    DEF TRACK_BOX Shape {
                      appearance USE BLACK
                      geometry Box {
                        size 0.098 0.003 0.0198
                      }
                    }
                  ]
                }
                Pose {
                  translation 0 0.0125 0.0099
                  children [
                    USE TRACK_BOX
                  ]
                }
              ]
            }
          ]
        }
        DEF RIGHT_TRACK Pose {
          translation 0 -0.0295 0.014
          rotation 1 0 0 1.57
          children [
            USE TRACK
          ]
        }
        DEF BASE Pose {
          translation 0 0 0.014
          children [
            Pose {
              translation -0.056 -5.91374e-08 0.02
              rotation 0 0 1 -1.5707953071795862
              children [
                Shape {
                  appearance PBRAppearance {
                    baseColor 0 0 0
                    roughness 1
                    metalness 0
                  }
                  geometry Box {
                    size 0.055 0.001 0.021
                  }
                }
              ]
              translationStep 0.001
            }
            Pose {
              translation -0.0182 0.026 0.014
              children [
                Shape {
                  appearance PBRAppearance {
                    baseColor 0 0 0
                    roughness 1
                    metalness 0
                  }
                  geometry Box {
                    size 0.075 0.001 0.034
                  }
                }
              ]
              translationStep 0.0001
            }
            Pose {
              translation -0.019 -0.0266 0.0145
              children [
                Shape {
                  appearance PBRAppearance {
                    baseColor 0 0 0
                    roughness 1
                    metalness 0
                  }
                  geometry Box {
                    size 0.075 0.001 0.034
                  }
                }
              ]
              translationStep 0.0001
            }
            Pose {
              translation -0.0466 -0.016 0.00562
              rotation 1 0 0 1.57
              children [
                DEF WHEEL_AXE Shape {
                  appearance PBRAppearance {
                    baseColor 0.392157 0.392157 0.392157
                    roughness 1
                    metalness 0
                  }
                  geometry Cylinder {
                    height 0.02
                    radius 0.0035
                  }
                }
              ]
              translationStep 0.0001
            }
            Pose {
              translation -0.0466 0.0159912 0.00562
              rotation 1 0 0 1.57
              children [
                USE WHEEL_AXE
              ]
              translationStep 0.001
            }
          ]
        }
        DEF FRONT_SUPPORT Pose {
          translation 0.0754 0 0.021
          children [
            DEF Composant Group {
              children [
                DEF ANTENNEGPS Pose {
                  translation -0.0427 -0.012 0.0118
                  children [
                    Solid {
                      translation 0 0 0.0312
                      children [
                        TrafficCone {
                          scale 0.03
                        }
                      ]
                      name "GPSComposant"
                      translationStep 0.0001
                    }
                    Solid {
                      translation 0 0 0.0314
                      children [
                        Shape {
                          appearance FlexibleAluminiumDuct {
                          }
                          geometry Cylinder {
                            height 0.0005
                            radius 0.02
                          }
                        }
                      ]
                      name "plaqueMetal"
                      translationStep 0.0001
                    }
                    Solid {
                      translation 0 0 0.0168
                      children [
                        Shape {
                          appearance PBRAppearance {
                            baseColor 1 0 0
                            roughness 1
                          }
                          geometry Cylinder {
                            height 0.03
                            radius 0.006
                          }
                        }
                      ]
                      name "colonne"
                      translationStep 0.0001
                    }
                    Shape {
                      appearance PBRAppearance {
                        baseColor 1 0 0
                        roughness 1
                      }
                      geometry Box {
                        size 0.026 0.023 0.003
                      }
                    }
                  ]
                  translationStep 0.0001
                }
                DEF CARTEMOTEUR Pose {
                  translation -0.1059 0.0112 0.0276
                  children [
                    Shape {
                      appearance PBRAppearance {
                        baseColorMap ImageTexture {
                          url [
                            "../pictures/carte_moteur.png"
                          ]
                        }
                        roughnessMap ImageTexture {
                        }
                        metalness 0
                        metalnessMap ImageTexture {
                          url [
                            "https://raw.githubusercontent.com/cyberbotics/webots/R2023b/projects/robots/surveyor/protos/textures/surveyor_serial_metalness.jpg"
                          ]
                        }
                        normalMap ImageTexture {
                          url [
                            "https://raw.githubusercontent.com/cyberbotics/webots/R2023b/projects/robots/surveyor/protos/textures/surveyor_serial_normal.jpg"
                          ]
                        }
                      }
                      geometry IndexedFaceSet {
                        coord Coordinate {
                          point [
                            0.017 -0.015 0.0031
                            -0.019 -0.015 0.0031
                            -0.019 0.015 0.0031
                            0.017 0.0145 0.0031
                          ]
                        }
                        texCoord TextureCoordinate {
                          point [
                            0 0
                            1 0
                            1 1
                            0 1
                          ]
                        }
                        coordIndex [
                          0, 3, 2, 1, -1
                        ]
                        texCoordIndex [
                          0, 1, 2, 3, -1
                        ]
                      }
                    }
                    Shape {
                      appearance USE BLACK
                      geometry Box {
                        size 0.031 0.028 0.006
                      }
                    }
                  ]
                  translationStep 0.0001
                }
                DEF BREADBOARD Pose {
                  translation -0.0718 0.0177 0.0274
                  children [
                    Shape {
                      appearance PBRAppearance {
                        baseColorMap ImageTexture {
                          url [
                            "../pictures/breadboard.jpg"
                          ]
                        }
                        roughnessMap ImageTexture {
                          url [
                            "https://raw.githubusercontent.com/cyberbotics/webots/R2023b/projects/robots/surveyor/protos/textures/surveyor_serial_roughness.jpg"
                          ]
                        }
                        metalness 0
                        metalnessMap ImageTexture {
                          url [
                            "https://raw.githubusercontent.com/cyberbotics/webots/R2023b/projects/robots/surveyor/protos/textures/surveyor_serial_metalness.jpg"
                          ]
                        }
                        normalMap ImageTexture {
                          url [
                            "https://raw.githubusercontent.com/cyberbotics/webots/R2023b/projects/robots/surveyor/protos/textures/surveyor_serial_normal.jpg"
                          ]
                        }
                      }
                      geometry IndexedFaceSet {
                        coord Coordinate {
                          point [
                            0.0105 0.0075 0.00251
                            0.0105 -0.0075 0.00251
                            -0.0105 -0.0072 0.00251
                            -0.0105 0.0072 0.00251
                          ]
                        }
                        texCoord TextureCoordinate {
                          point [
                            0 0
                            1 0
                            1 1
                            0 1
                          ]
                        }
                        coordIndex [
                          0, 3, 2, 1, -1
                        ]
                        texCoordIndex [
                          0, 1, 2, 3, -1
                        ]
                      }
                    }
                    Shape {
                      appearance PBRAppearance {
                        baseColor 0.870588 0.870588 0.870588
                        roughness 1
                        metalness 0
                      }
                      geometry Box {
                        size 0.021 0.015 0.005
                      }
                    }
                  ]
                  translationStep 0.0001
                }
                DEF RADIO Pose {
                  translation -0.0344 0.0118 0.013
                  rotation 0 0 1 3.14159
                  children [
                    Shape {
                      appearance PBRAppearance {
                        baseColorMap ImageTexture {
                          url [
                            "../pictures/ModuleRadio.png"
                          ]
                        }
                        roughnessMap ImageTexture {
                          url [
                            "https://raw.githubusercontent.com/cyberbotics/webots/R2023b/projects/robots/surveyor/protos/textures/surveyor_serial_roughness.jpg"
                          ]
                        }
                        metalnessMap ImageTexture {
                          url [
                            "https://raw.githubusercontent.com/cyberbotics/webots/R2023b/projects/robots/surveyor/protos/textures/surveyor_serial_metalness.jpg"
                          ]
                        }
                        normalMap ImageTexture {
                          url [
                            "https://raw.githubusercontent.com/cyberbotics/webots/R2023b/projects/robots/surveyor/protos/textures/surveyor_serial_normal.jpg"
                          ]
                        }
                      }
                      geometry IndexedFaceSet {
                        coord Coordinate {
                          point [
                            0.01 -0.0035 0.0016
                            -0.01 -0.0035 0.0016
                            -0.01 0.0035 0.0016
                            0.01 0.0035 0.0016
                          ]
                        }
                        texCoord TextureCoordinate {
                          point [
                            0 0
                            1 0
                            1 1
                            0 1
                          ]
                        }
                        coordIndex [
                          0, 3, 2, 1, -1
                        ]
                        texCoordIndex [
                          0, 1, 2, 3, -1
                        ]
                      }
                    }
                    Shape {
                      appearance USE BLACK
                      geometry Box {
                        size 0.02 0.007 0.003
                      }
                    }
                  ]
                  translationStep 0.0001
                }
                DEF ARDUINOR4 Pose {
                  translation -0.1044 -0.0158 0.0264
                  children [
                    Shape {
                      appearance PBRAppearance {
                        baseColorMap ImageTexture {
                          url [
                            "../pictures/UnoR4Wifi.png"
                          ]
                          filtering 3
                        }
                        roughnessMap ImageTexture {
                          url [
                            "https://raw.githubusercontent.com/cyberbotics/webots/R2023b/projects/robots/surveyor/protos/textures/surveyor_serial_roughness.jpg"
                          ]
                        }
                        metalness 0
                        metalnessMap ImageTexture {
                          url [
                            "https://raw.githubusercontent.com/cyberbotics/webots/R2023b/projects/robots/surveyor/protos/textures/surveyor_serial_metalness.jpg"
                          ]
                        }
                        normalMap ImageTexture {
                          url [
                            "https://raw.githubusercontent.com/cyberbotics/webots/R2023b/projects/robots/surveyor/protos/textures/surveyor_serial_normal.jpg"
                          ]
                        }
                      }
                      geometry IndexedFaceSet {
                        coord Coordinate {
                          point [
                            -0.0184 -0.01 0.00151
                            -0.0183 0.01 0.00151
                            0.0185 0.01 0.00151
                            0.0185 -0.01 0.00151
                          ]
                        }
                        texCoord TextureCoordinate {
                          point [
                            0 0
                            1 0
                            1 1
                            0 1
                          ]
                        }
                        coordIndex [
                          0, 3, 2, 1, -1
                        ]
                        texCoordIndex [
                          0, 1, 2, 3, -1
                        ]
                      }
                    }
                    Shape {
                      appearance USE BLACK
                      geometry Box {
                        size 0.037 0.02 0.003
                      }
                    }
                  ]
                }
              ]
            }
            DEF SUPPORT Group {
              children [
                Pose {
                  translation -0.0364 0 -0.004
                  children [
                    Shape {
                      appearance DEF BlackRobotAlphie PBRAppearance {
                        baseColor 0 0 0
                        roughness 1
                        metalness 0
                        name ""
                      }
                      geometry Box {
                        size 0.04 0.0525 0.0011
                      }
                    }
                  ]
                  translationStep 0.001
                }
                Pose {
                  translation -0.0433 0 0.0102
                  children [
                    Shape {
                      appearance DEF BlackRobotAlphie PBRAppearance {
                        baseColor 0 0 0
                        roughness 1
                        metalness 0
                        name ""
                      }
                      geometry Box {
                        size 0.03 0.0525 0.0011
                      }
                    }
                  ]
                  translationStep 0.0001
                }
                Shape {
                  appearance PBRAppearance {
                    baseColor 0.85098 0.85098 0.85098
                    baseColorMap ImageTexture {
                      url [
                        "../pictures/FrontAlphie.png"
                      ]
                      repeatS FALSE
                      repeatT FALSE
                    }
                    roughness 1
                    roughnessMap ImageTexture {
                      url [
                        "https://raw.githubusercontent.com/cyberbotics/webots/R2023b/projects/robots/surveyor/protos/textures/surveyor_top_roughness.jpg"
                      ]
                    }
                    metalness 0
                    metalnessMap ImageTexture {
                      url [
                        "https://raw.githubusercontent.com/cyberbotics/webots/R2023b/projects/robots/surveyor/protos/textures/surveyor_top_metalness.jpg"
                      ]
                    }
                    normalMap ImageTexture {
                      url [
                        "https://raw.githubusercontent.com/cyberbotics/webots/R2023b/projects/robots/surveyor/protos/textures/surveyor_top_normal.jpg"
                      ]
                    }
                  }
                  geometry IndexedFaceSet {
                    coord Coordinate {
                      point [
                        -0.059 0.026 0.011
                        -0.028 0.026 0.011
                        -0.028 -0.026 0.011
                        -0.059 -0.026 0.011
                      ]
                    }
                    texCoord TextureCoordinate {
                      point [
                        0 0
                        1 0
                        1 1
                        0 1
                      ]
                    }
                    coordIndex [
                      0, 3, 2, 1, -1
                    ]
                    texCoordIndex [
                      0, 1, 2, 3, -1
                    ]
                  }
                }
                Pose {
                  translation -0.0227073 3.05188e-07 0.00330141
                  rotation -0.6848107156457631 0.6848157156436869 -0.2491218965570118 2.65328
                  children [
                    Shape {
                      appearance USE BlackRobotAlphie
                      geometry Box {
                        size 0.0525 0.0012 0.0185
                      }
                    }
                  ]
                  translationStep 0.0001
                }
              ]
            }
          ]
        }
        DEF TOP_PLATE Group {
          children [
            Pose {
              translation -0.0186 0 0.0449
              children [
                Shape {
                  appearance PBRAppearance {
                    baseColor 0 0 0
                    roughness 1
                    metalness 0
                  }
                  geometry Box {
                    size 0.076 0.053 0.0015
                  }
                }
              ]
              translationStep 0.001
            }
            DEF TOP Pose {
              translation -0.006 -6.36861e-08 0.0477
              rotation 0 0 1 3.14159
              children [
                GPS {
                  rotation 0 0 1 3.14159
                }
                Compass {
                  rotation 0 0 1 3.14159
                }
                Shape {
                  appearance PBRAppearance {
                    baseColorMap ImageTexture {
                      url [
                        "../pictures/TopAlphie.png"
                      ]
                      repeatS FALSE
                      repeatT FALSE
                    }
                    roughness 1
                    roughnessMap ImageTexture {
                      url [
                        "https://raw.githubusercontent.com/cyberbotics/webots/R2023b/projects/robots/surveyor/protos/textures/surveyor_top_roughness.jpg"
                      ]
                    }
                    metalness 0
                    metalnessMap ImageTexture {
                      url [
                        "https://raw.githubusercontent.com/cyberbotics/webots/R2023b/projects/robots/surveyor/protos/textures/surveyor_top_metalness.jpg"
                      ]
                    }
                    normalMap ImageTexture {
                      url [
                        "https://raw.githubusercontent.com/cyberbotics/webots/R2023b/projects/robots/surveyor/protos/textures/surveyor_top_normal.jpg"
                      ]
                    }
                  }
                  geometry IndexedFaceSet {
                    coord Coordinate {
                      point [
                        0.05 -0.027 -0.002
                        -0.026 -0.027 -0.002
                        -0.026 0.027 -0.002
                        0.05 0.027 -0.002
                      ]
                    }
                    texCoord TextureCoordinate {
                      point [
                        0 0
                        1 0
                        1 1
                        0 1
                      ]
                    }
                    coordIndex [
                      0, 3, 2, 1, -1
                    ]
                    texCoordIndex [
                      0, 1, 2, 3, -1
                    ]
                  }
                }
              ]
              translationStep 0.001
            }
          ]
        }
        DEF BATTERIES Group {
          children [
            Pose {
              translation -0.0220079 -5.51926e-08 0.0270237
              rotation 0.577656895078166 -0.5771968951617173 0.5771968951617173 2.09394
              children [
                DEF BATTERY Shape {
                  appearance DEF BlackRobot PBRAppearance {
                    baseColor 0.360784 0.360784 0.360784
                    roughness 1
                    metalness 0
                  }
                  geometry Box {
                    size 0.015 0.02 0.05
                  }
                }
              ]
            }
          ]
        }
      ]
    }
    DEF ANTENNA_EMITTER Emitter {
      translation 0.0451 0.0118 0.037
      children [
        DEF RangeEmitter Shape {
          appearance PBRAppearance {
            transparency 0.8
            roughness 1
            metalness 0
          }
          geometry Sphere {
            radius 1.5
            subdivision 5
          }
        }
        Pose {
          translation 0 0 -0.008
          children [
            Shape {
              appearance USE BLACK
              geometry Cylinder {
                height 0.019
                radius 0.0006
              }
            }
          ]
        }
        Pose {
          children [
            Shape {
              appearance USE BLACK
              geometry Cylinder {
                height 0.007
                radius 0.0015
              }
            }
          ]
        }
      ]
      translationStep 0.0001
      range 1.5
    }
    DEF ANTENNA_RECEIVER Receiver {
      translation 0.0451 0.0118 0.037
    }
    DEF FIRST_LEFT_WHEEL HingeJoint {
      jointParameters HingeJointParameters {
        position -9597.877033673038
        axis 0 -1 0
        anchor 0.049 0.0394 0.014
      }
      device [
        RotationalMotor {
          name "wheel_motor00"
          maxVelocity 50
        }
        PositionSensor {
          name "wheel_sensor00"
        }
      ]
      endPoint Solid {
        translation 0.049 0.0394 0.014
        rotation 0 -0.9999999999999999 0 2.8301156973704784
        name "first left wheel"
        contactMaterial "wheel"
        boundingObject DEF BOUNDING_WHEEL Pose {
          rotation 1 0 0 -1.57
          children [
            Cylinder {
              height 0.0198
              radius 0.014
            }
          ]
        }
        physics DEF PHYSICS_FRONT_WHEEL Physics {
          density -1
          mass 0.005
        }
      }
    }
    DEF SECOND_LEFT_WHEEL HingeJoint {
      jointParameters HingeJointParameters {
        position -7649.041629830484
        axis 0 -1 0
        anchor 0.0245 0.0394 0.014
      }
      device [
        RotationalMotor {
          name "wheel_motor01"
          maxVelocity 50
        }
        PositionSensor {
          name "wheel_sensor01"
        }
      ]
      endPoint Solid {
        translation 0.0245 0.0394 0.014
        rotation 0 -0.9999999999999999 0 3.878074314251876
        name "second left wheel"
        contactMaterial "wheel"
        boundingObject USE BOUNDING_WHEEL
        physics USE PHYSICS_FRONT_WHEEL
      }
    }
    DEF THIRD_LEFT_WHEEL HingeJoint {
      jointParameters HingeJointParameters {
        position -9570.838446196438
        axis 0 -1 0
        anchor 0 0.0394 0.014
      }
      device [
        RotationalMotor {
          name "wheel_motor02"
          maxVelocity 50
        }
        PositionSensor {
          name "wheel_sensor02"
        }
      ]
      endPoint Solid {
        translation 0 0.0394 0.014
        rotation 0 -0.9999999999999999 0 4.735961945251919
        name "third left wheel"
        contactMaterial "center_wheel"
        boundingObject USE BOUNDING_WHEEL
        physics DEF PHYSICS_CENTER_WHEEL Physics {
          density -1
          mass 0.005
        }
      }
    }
    DEF FOURTH_LEFT_WHEEL HingeJoint {
      jointParameters HingeJointParameters {
        position -9570.838455447849
        axis 0 -1 0
        anchor -0.0245 0.0394 0.014
      }
      device [
        RotationalMotor {
          name "wheel_motor03"
          maxVelocity 50
        }
        PositionSensor {
          name "wheel_sensor03"
        }
      ]
      endPoint Solid {
        translation -0.0245 0.0394 0.014
        rotation 0 -1 0 4.73595269384089
        name "fourth left wheel"
        contactMaterial "wheel"
        boundingObject USE BOUNDING_WHEEL
        physics USE PHYSICS_FRONT_WHEEL
      }
    }
    DEF LAST_LEFT_WHEEL HingeJoint {
      jointParameters HingeJointParameters {
        position -9570.838446135767
        axis 0 -1 0
        anchor -0.049 0.0394 0.014
      }
      device [
        RotationalMotor {
          name "wheel_motor04"
          maxVelocity 50
        }
        PositionSensor {
          name "wheel_sensor04"
        }
      ]
      endPoint Solid {
        translation -0.049 0.0394 0.014
        rotation 0 -1 0 4.735962005922492
        name "last left wheel"
        contactMaterial "wheel"
        boundingObject USE BOUNDING_WHEEL
        physics USE PHYSICS_FRONT_WHEEL
      }
    }
    DEF FIRST_RIGHT_WHEEL HingeJoint {
      jointParameters HingeJointParameters {
        position -9691.207934757702
        axis 0 -1 0
        anchor 0.049 -0.0394 0.014
      }
      device [
        RotationalMotor {
          name "wheel_motor05"
          maxVelocity 50
        }
        PositionSensor {
          name "wheel_sensor05"
        }
      ]
      endPoint Solid {
        translation 0.049 -0.0394 0.014
        rotation 0 1 0 2.5361910867795308
        name "first right wheel"
        contactMaterial "wheel"
        boundingObject USE BOUNDING_WHEEL
        physics USE PHYSICS_FRONT_WHEEL
      }
    }
    DEF SECOND_RIGHT_WHEEL HingeJoint {
      jointParameters HingeJointParameters {
        position -9691.207934616661
        axis 0 -1 0
        anchor 0.0245 -0.0394 0.014
      }
      device [
        RotationalMotor {
          name "wheel_motor06"
          maxVelocity 50
        }
        PositionSensor {
          name "wheel_sensor06"
        }
      ]
      endPoint Solid {
        translation 0.0245 -0.0394 0.014
        rotation 0 1 0 2.5361909457387304
        name "second right wheel"
        contactMaterial "wheel"
        boundingObject USE BOUNDING_WHEEL
        physics USE PHYSICS_FRONT_WHEEL
      }
    }
    DEF THIRD_RIGHT_WHEEL HingeJoint {
      jointParameters HingeJointParameters {
        position -9691.207943221716
        axis 0 -1 0
        anchor 0 -0.0394 0.014
      }
      device [
        RotationalMotor {
          name "wheel_motor07"
          maxVelocity 50
        }
        PositionSensor {
          name "wheel_sensor07"
        }
      ]
      endPoint Solid {
        translation 0 -0.0394 0.014
        rotation 0 1 0 2.536199550793703
        name "third right wheel"
        contactMaterial "center_wheel"
        boundingObject USE BOUNDING_WHEEL
        physics USE PHYSICS_CENTER_WHEEL
      }
    }
    DEF FOURTH_RIGHT_WHEEL HingeJoint {
      jointParameters HingeJointParameters {
        position -9691.2079550895
        axis 0 -1 0
        anchor -0.0245 -0.0394 0.014
      }
      device [
        RotationalMotor {
          name "wheel_motor08"
          maxVelocity 50
        }
        PositionSensor {
          name "wheel_sensor08"
        }
      ]
      endPoint Solid {
        translation -0.0245 -0.0394 0.014
        rotation 0 1 0 2.5362114185772446
        name "forth right wheel"
        contactMaterial "wheel"
        boundingObject USE BOUNDING_WHEEL
        physics USE PHYSICS_FRONT_WHEEL
      }
    }
    DEF LAST_RIGHT_WHEEL HingeJoint {
      jointParameters HingeJointParameters {
        position -9691.20795171104
        axis 0 -1 0
        anchor -0.049 -0.0394 0.014
      }
      device [
        RotationalMotor {
          name "wheel_motor09"
          maxVelocity 50
        }
        PositionSensor {
          name "wheel_sensor09"
        }
      ]
      endPoint Solid {
        translation -0.049 -0.0394 0.014
        rotation 0 1 0 2.5362080401172937
        name "last right wheel"
        contactMaterial "wheel"
        boundingObject USE BOUNDING_WHEEL
        physics USE PHYSICS_FRONT_WHEEL
      }
    }
  ]
  name "Alphie"
  model "Alphie'sModel"
  description "Simulation of the real robot Alphie"
  boundingObject Group {
    children [
      Pose {
        translation 0 0 0.04
        children [
          Box {
            size 0.125 0.1 0.07
          }
        ]
      }
    ]
  }
  physics Physics {
    density -1
    mass 0.324
    centerOfMass [
      -0.005 0 0.028
    ]
    inertiaMatrix [
      0.000267079 0.000473553 0.000418585
      0 -6.02166e-06 0
    ]
  }
  controller "MainController"
}
Robot {
  translation 1.25259 0.764796 -0.0001144
  rotation -2.557260591886361e-05 6.183924629609812e-05 0.9999999977609748 1.3718482359039352
  children [
    Group {
    }
    DEF BODY Group {
      children [
        DEF LEFT_TRACK Pose {
          translation 0 0.0295 0.014
          rotation 1 0 0 -1.57
          children [
            DEF TRACK Group {
              children [
                Pose {
                  translation -0.049 0 0
                  children [
                    DEF TRACK_EXTRUSION Shape {
                      appearance DEF BLACK PBRAppearance {
                        baseColor 0 0 0
                        roughness 0.7
                        metalness 0
                      }
                      geometry IndexedFaceSet {
                        coord Coordinate {
                          point [
                            0 0.014 0
                            -0.007 0.01212 0
                            -0.01212 0.007 0
                            -0.014 0 0
                            -0.01212 -0.007 0
                            -0.007 -0.01212 0
                            0 -0.014 0
                            0 0.014 0
                            0 0.014 0.0198
                            -0.007 0.01212 0.0198
                            -0.01212 0.007 0.0198
                            -0.014 0 0.0198
                            -0.01212 -0.007 0.0198
                            -0.007 -0.01212 0.0198
                            0 -0.014 0.0198
                            0 0.014 0.0198
                          ]
                        }
                        coordIndex [
                          7, 6, 5, 4, 3, 2, 1, 0, -1, 8, 9, 10, 11, 12, 13, 14, 15, -1, 0, 1, 9, 8, -1, 1, 2, 10, 9, -1, 2, 3, 11, 10, -1, 3, 4, 12, 11, -1, 4, 5, 13, 12, -1, 5, 6, 14, 13, -1, 6, 7, 15, 14, -1
                        ]
                      }
                    }
                  ]
                }
                Pose {
                  translation 0.049 0 0
                  rotation 0 0 1 3.14
                  children [
                    DEF TRACK_EXTRUSION Shape {
                      appearance USE BLACK
                      geometry IndexedFaceSet {
                        coord Coordinate {
                          point [
                            0 0.014 0
                            -0.007 0.01212 0
                            -0.01212 0.007 0
                            -0.014 0 0
                            -0.01212 -0.007 0
                            -0.007 -0.01212 0
                            0 -0.014 0
                            0 0.014 0
                            0 0.014 0.0198
                            -0.007 0.01212 0.0198
                            -0.01212 0.007 0.0198
                            -0.014 0 0.0198
                            -0.01212 -0.007 0.0198
                            -0.007 -0.01212 0.0198
                            0 -0.014 0.0198
                            0 0.014 0.0198
                          ]
                        }
                        coordIndex [
                          7, 6, 5, 4, 3, 2, 1, 0, -1, 8, 9, 10, 11, 12, 13, 14, 15, -1, 0, 1, 9, 8, -1, 1, 2, 10, 9, -1, 2, 3, 11, 10, -1, 3, 4, 12, 11, -1, 4, 5, 13, 12, -1, 5, 6, 14, 13, -1, 6, 7, 15, 14, -1
                        ]
                      }
                    }
                  ]
                }
                Pose {
                  translation 0.049 0 0.0101
                  children [
                    DEF TRACK_WHEEL Shape {
                      appearance DEF GRAY PBRAppearance {
                        roughness 0.2
                      }
                      geometry Cylinder {
                        height 0.0205
                        radius 0.011
                      }
                    }
                  ]
                }
                Pose {
                  translation -0.049 0 0.0101
                  children [
                    USE TRACK_WHEEL
                  ]
                }
                Pose {
                  translation 0 -0.0125 0.0099
                  children [
                    DEF TRACK_BOX Shape {
                      appearance USE BLACK
                      geometry Box {
                        size 0.098 0.003 0.0198
                      }
                    }
                  ]
                }
                Pose {
                  translation 0 0.0125 0.0099
                  children [
                    USE TRACK_BOX
                  ]
                }
              ]
            }
          ]
        }
        DEF RIGHT_TRACK Pose {
          translation 0 -0.0295 0.014
          rotation 1 0 0 1.57
          children [
            USE TRACK
          ]
        }
        DEF BASE Pose {
          translation 0 0 0.014
          children [
            Pose {
              translation -0.056 -5.91374e-08 0.02
              rotation 0 0 1 -1.5707953071795862
              children [
                Shape {
                  appearance PBRAppearance {
                    baseColor 0 0 0
                    roughness 1
                    metalness 0
                  }
                  geometry Box {
                    size 0.055 0.001 0.021
                  }
                }
              ]
              translationStep 0.001
            }
            Pose {
              translation -0.0182 0.026 0.014
              children [
                Shape {
                  appearance PBRAppearance {
                    baseColor 0 0 0
                    roughness 1
                    metalness 0
                  }
                  geometry Box {
                    size 0.075 0.001 0.034
                  }
                }
              ]
              translationStep 0.0001
            }
            Pose {
              translation -0.019 -0.0266 0.0145
              children [
                Shape {
                  appearance PBRAppearance {
                    baseColor 0 0 0
                    roughness 1
                    metalness 0
                  }
                  geometry Box {
                    size 0.075 0.001 0.034
                  }
                }
              ]
              translationStep 0.0001
            }
            Pose {
              translation -0.0466 -0.016 0.00562
              rotation 1 0 0 1.57
              children [
                DEF WHEEL_AXE Shape {
                  appearance PBRAppearance {
                    baseColor 0.392157 0.392157 0.392157
                    roughness 1
                    metalness 0
                  }
                  geometry Cylinder {
                    height 0.02
                    radius 0.0035
                  }
                }
              ]
              translationStep 0.0001
            }
            Pose {
              translation -0.0466 0.0159912 0.00562
              rotation 1 0 0 1.57
              children [
                USE WHEEL_AXE
              ]
              translationStep 0.001
            }
          ]
        }
        DEF FRONT_SUPPORT Pose {
          translation 0.0754 0 0.021
          children [
            DEF Composant Group {
              children [
                DEF ANTENNEGPS Pose {
                  translation -0.0427 -0.012 0.0118
                  children [
                    Solid {
                      translation 0 0 0.0312
                      children [
                        TrafficCone {
                          scale 0.03
                        }
                      ]
                      name "GPSComposant"
                      translationStep 0.0001
                    }
                    Solid {
                      translation 0 0 0.0314
                      children [
                        Shape {
                          appearance FlexibleAluminiumDuct {
                          }
                          geometry Cylinder {
                            height 0.0005
                            radius 0.02
                          }
                        }
                      ]
                      name "plaqueMetal"
                      translationStep 0.0001
                    }
                    Solid {
                      translation 0 0 0.0168
                      children [
                        Shape {
                          appearance PBRAppearance {
                            baseColor 1 0 0
                            roughness 1
                          }
                          geometry Cylinder {
                            height 0.03
                            radius 0.006
                          }
                        }
                      ]
                      name "colonne"
                      translationStep 0.0001
                    }
                    Shape {
                      appearance PBRAppearance {
                        baseColor 1 0 0
                        roughness 1
                      }
                      geometry Box {
                        size 0.026 0.023 0.003
                      }
                    }
                  ]
                  translationStep 0.0001
                }
                DEF CARTEMOTEUR Pose {
                  translation -0.1059 0.0112 0.0276
                  children [
                    Shape {
                      appearance PBRAppearance {
                        baseColorMap ImageTexture {
                          url [
                            "../pictures/carte_moteur.png"
                          ]
                        }
                        roughnessMap ImageTexture {
                        }
                        metalness 0
                        metalnessMap ImageTexture {
                          url [
                            "https://raw.githubusercontent.com/cyberbotics/webots/R2023b/projects/robots/surveyor/protos/textures/surveyor_serial_metalness.jpg"
                          ]
                        }
                        normalMap ImageTexture {
                          url [
                            "https://raw.githubusercontent.com/cyberbotics/webots/R2023b/projects/robots/surveyor/protos/textures/surveyor_serial_normal.jpg"
                          ]
                        }
                      }
                      geometry IndexedFaceSet {
                        coord Coordinate {
                          point [
                            0.017 -0.015 0.0031
                            -0.019 -0.015 0.0031
                            -0.019 0.015 0.0031
                            0.017 0.0145 0.0031
                          ]
                        }
                        texCoord TextureCoordinate {
                          point [
                            0 0
                            1 0
                            1 1
                            0 1
                          ]
                        }
                        coordIndex [
                          0, 3, 2, 1, -1
                        ]
                        texCoordIndex [
                          0, 1, 2, 3, -1
                        ]
                      }
                    }
                    Shape {
                      appearance USE BLACK
                      geometry Box {
                        size 0.031 0.028 0.006
                      }
                    }
                  ]
                  translationStep 0.0001
                }
                DEF BREADBOARD Pose {
                  translation -0.0718 0.0177 0.0274
                  children [
                    Shape {
                      appearance PBRAppearance {
                        baseColorMap ImageTexture {
                          url [
                            "../pictures/breadboard.jpg"
                          ]
                        }
                        roughnessMap ImageTexture {
                          url [
                            "https://raw.githubusercontent.com/cyberbotics/webots/R2023b/projects/robots/surveyor/protos/textures/surveyor_serial_roughness.jpg"
                          ]
                        }
                        metalness 0
                        metalnessMap ImageTexture {
                          url [
                            "https://raw.githubusercontent.com/cyberbotics/webots/R2023b/projects/robots/surveyor/protos/textures/surveyor_serial_metalness.jpg"
                          ]
                        }
                        normalMap ImageTexture {
                          url [
                            "https://raw.githubusercontent.com/cyberbotics/webots/R2023b/projects/robots/surveyor/protos/textures/surveyor_serial_normal.jpg"
                          ]
                        }
                      }
                      geometry IndexedFaceSet {
                        coord Coordinate {
                          point [
                            0.0105 0.0075 0.00251
                            0.0105 -0.0075 0.00251
                            -0.0105 -0.0072 0.00251
                            -0.0105 0.0072 0.00251
                          ]
                        }
                        texCoord TextureCoordinate {
                          point [
                            0 0
                            1 0
                            1 1
                            0 1
                          ]
                        }
                        coordIndex [
                          0, 3, 2, 1, -1
                        ]
                        texCoordIndex [
                          0, 1, 2, 3, -1
                        ]
                      }
                    }
                    Shape {
                      appearance PBRAppearance {
                        baseColor 0.870588 0.870588 0.870588
                        roughness 1
                        metalness 0
                      }
                      geometry Box {
                        size 0.021 0.015 0.005
                      }
                    }
                  ]
                  translationStep 0.0001
                }
                DEF RADIO Pose {
                  translation -0.0344 0.0118 0.013
                  rotation 0 0 1 3.14159
                  children [
                    Shape {
                      appearance PBRAppearance {
                        baseColorMap ImageTexture {
                          url [
                            "../pictures/ModuleRadio.png"
                          ]
                        }
                        roughnessMap ImageTexture {
                          url [
                            "https://raw.githubusercontent.com/cyberbotics/webots/R2023b/projects/robots/surveyor/protos/textures/surveyor_serial_roughness.jpg"
                          ]
                        }
                        metalnessMap ImageTexture {
                          url [
                            "https://raw.githubusercontent.com/cyberbotics/webots/R2023b/projects/robots/surveyor/protos/textures/surveyor_serial_metalness.jpg"
                          ]
                        }
                        normalMap ImageTexture {
                          url [
                            "https://raw.githubusercontent.com/cyberbotics/webots/R2023b/projects/robots/surveyor/protos/textures/surveyor_serial_normal.jpg"
                          ]
                        }
                      }
                      geometry IndexedFaceSet {
                        coord Coordinate {
                          point [
                            0.01 -0.0035 0.0016
                            -0.01 -0.0035 0.0016
                            -0.01 0.0035 0.0016
                            0.01 0.0035 0.0016
                          ]
                        }
                        texCoord TextureCoordinate {
                          point [
                            0 0
                            1 0
                            1 1
                            0 1
                          ]
                        }
                        coordIndex [
                          0, 3, 2, 1, -1
                        ]
                        texCoordIndex [
                          0, 1, 2, 3, -1
                        ]
                      }
                    }
                    Shape {
                      appearance USE BLACK
                      geometry Box {
                        size 0.02 0.007 0.003
                      }
                    }
                  ]
                  translationStep 0.0001
                }
                DEF ARDUINOR4 Pose {
                  translation -0.1044 -0.0158 0.0264
                  children [
                    Shape {
                      appearance PBRAppearance {
                        baseColorMap ImageTexture {
                          url [
                            "../pictures/UnoR4Wifi.png"
                          ]
                          filtering 3
                        }
                        roughnessMap ImageTexture {
                          url [
                            "https://raw.githubusercontent.com/cyberbotics/webots/R2023b/projects/robots/surveyor/protos/textures/surveyor_serial_roughness.jpg"
                          ]
                        }
                        metalness 0
                        metalnessMap ImageTexture {
                          url [
                            "https://raw.githubusercontent.com/cyberbotics/webots/R2023b/projects/robots/surveyor/protos/textures/surveyor_serial_metalness.jpg"
                          ]
                        }
                        normalMap ImageTexture {
                          url [
                            "https://raw.githubusercontent.com/cyberbotics/webots/R2023b/projects/robots/surveyor/protos/textures/surveyor_serial_normal.jpg"
                          ]
                        }
                      }
                      geometry IndexedFaceSet {
                        coord Coordinate {
                          point [
                            -0.0184 -0.01 0.00151
                            -0.0183 0.01 0.00151
                            0.0185 0.01 0.00151
                            0.0185 -0.01 0.00151
                          ]
                        }
                        texCoord TextureCoordinate {
                          point [
                            0 0
                            1 0
                            1 1
                            0 1
                          ]
                        }
                        coordIndex [
                          0, 3, 2, 1, -1
                        ]
                        texCoordIndex [
                          0, 1, 2, 3, -1
                        ]
                      }
                    }
                    Shape {
                      appearance USE BLACK
                      geometry Box {
                        size 0.037 0.02 0.003
                      }
                    }
                  ]
                }
              ]
            }
            DEF SUPPORT Group {
              children [
                Pose {
                  translation -0.0364 0 -0.004
                  children [
                    Shape {
                      appearance DEF BlackRobotAlphie PBRAppearance {
                        baseColor 0 0 0
                        roughness 1
                        metalness 0
                        name ""
                      }
                      geometry Box {
                        size 0.04 0.0525 0.0011
                      }
                    }
                  ]
                  translationStep 0.001
                }
                Pose {
                  translation -0.0433 0 0.0102
                  children [
                    Shape {
                      appearance DEF BlackRobotAlphie PBRAppearance {
                        baseColor 0 0 0
                        roughness 1
                        metalness 0
                        name ""
                      }
                      geometry Box {
                        size 0.03 0.0525 0.0011
                      }
                    }
                  ]
                  translationStep 0.0001
                }
                Shape {
                  appearance PBRAppearance {
                    baseColor 0.85098 0.85098 0.85098
                    baseColorMap ImageTexture {
                      url [
                        "../pictures/FrontAlphie.png"
                      ]
                      repeatS FALSE
                      repeatT FALSE
                    }
                    roughness 1
                    roughnessMap ImageTexture {
                      url [
                        "https://raw.githubusercontent.com/cyberbotics/webots/R2023b/projects/robots/surveyor/protos/textures/surveyor_top_roughness.jpg"
                      ]
                    }
                    metalness 0
                    metalnessMap ImageTexture {
                      url [
                        "https://raw.githubusercontent.com/cyberbotics/webots/R2023b/projects/robots/surveyor/protos/textures/surveyor_top_metalness.jpg"
                      ]
                    }
                    normalMap ImageTexture {
                      url [
                        "https://raw.githubusercontent.com/cyberbotics/webots/R2023b/projects/robots/surveyor/protos/textures/surveyor_top_normal.jpg"
                      ]
                    }
                  }
                  geometry IndexedFaceSet {
                    coord Coordinate {
                      point [
                        -0.059 0.026 0.011
                        -0.028 0.026 0.011
                        -0.028 -0.026 0.011
                        -0.059 -0.026 0.011
                      ]
                    }
                    texCoord TextureCoordinate {
                      point [
                        0 0
                        1 0
                        1 1
                        0 1
                      ]
                    }
                    coordIndex [
                      0, 3, 2, 1, -1
                    ]
                    texCoordIndex [
                      0, 1, 2, 3, -1
                    ]
                  }
                }
                Pose {
                  translation -0.0227073 3.05188e-07 0.00330141
                  rotation -0.6848107156457631 0.6848157156436869 -0.2491218965570118 2.65328
                  children [
                    Shape {
                      appearance USE BlackRobotAlphie
                      geometry Box {
                        size 0.0525 0.0012 0.0185
                      }
                    }
                  ]
                  translationStep 0.0001
                }
              ]
            }
          ]
        }
        DEF TOP_PLATE Group {
          children [
            Pose {
              translation -0.0186 0 0.0449
              children [
                Shape {
                  appearance PBRAppearance {
                    baseColor 0 0 0
                    roughness 1
                    metalness 0
                  }
                  geometry Box {
                    size 0.076 0.053 0.0015
                  }
                }
              ]
              translationStep 0.001
            }
            DEF TOP Pose {
              translation -0.006 -6.36861e-08 0.0477
              rotation 0 0 1 3.14159
              children [
                GPS {
                  rotation 0 0 1 3.14159
                }
                Compass {
                  rotation 0 0 1 3.14159
                }
                Shape {
                  appearance PBRAppearance {
                    baseColorMap ImageTexture {
                      url [
                        "../pictures/TopAlphie.png"
                      ]
                      repeatS FALSE
                      repeatT FALSE
                    }
                    roughness 1
                    roughnessMap ImageTexture {
                      url [
                        "https://raw.githubusercontent.com/cyberbotics/webots/R2023b/projects/robots/surveyor/protos/textures/surveyor_top_roughness.jpg"
                      ]
                    }
                    metalness 0
                    metalnessMap ImageTexture {
                      url [
                        "https://raw.githubusercontent.com/cyberbotics/webots/R2023b/projects/robots/surveyor/protos/textures/surveyor_top_metalness.jpg"
                      ]
                    }
                    normalMap ImageTexture {
                      url [
                        "https://raw.githubusercontent.com/cyberbotics/webots/R2023b/projects/robots/surveyor/protos/textures/surveyor_top_normal.jpg"
                      ]
                    }
                  }
                  geometry IndexedFaceSet {
                    coord Coordinate {
                      point [
                        0.05 -0.027 -0.002
                        -0.026 -0.027 -0.002
                        -0.026 0.027 -0.002
                        0.05 0.027 -0.002
                      ]
                    }
                    texCoord TextureCoordinate {
                      point [
                        0 0
                        1 0
                        1 1
                        0 1
                      ]
                    }
                    coordIndex [
                      0, 3, 2, 1, -1
                    ]
                    texCoordIndex [
                      0, 1, 2, 3, -1
                    ]
                  }
                }
              ]
              translationStep 0.001
            }
          ]
        }
        DEF BATTERIES Group {
          children [
            Pose {
              translation -0.0220079 -5.51926e-08 0.0270237
              rotation 0.577656895078166 -0.5771968951617173 0.5771968951617173 2.09394
              children [
                DEF BATTERY Shape {
                  appearance DEF BlackRobot PBRAppearance {
                    baseColor 0.360784 0.360784 0.360784
                    roughness 1
                    metalness 0
                  }
                  geometry Box {
                    size 0.015 0.02 0.05
                  }
                }
              ]
            }
          ]
        }
      ]
    }
    DEF ANTENNA_EMITTER Emitter {
      translation 0.0451 0.0118 0.037
      children [
        DEF RangeEmitter Shape {
          appearance PBRAppearance {
            transparency 0.8
            roughness 1
            metalness 0
          }
          geometry Sphere {
            radius 1.5
            subdivision 5
          }
        }
        Pose {
          translation 0 0 -0.008
          children [
            Shape {
              appearance USE BLACK
              geometry Cylinder {
                height 0.019
                radius 0.0006
              }
            }
          ]
        }
        Pose {
          children [
            Shape {
              appearance USE BLACK
              geometry Cylinder {
                height 0.007
                radius 0.0015
              }
            }
          ]
        }
      ]
      translationStep 0.0001
      range 1.5
    }
    DEF ANTENNA_RECEIVER Receiver {
      translation 0.0451 0.0118 0.037
    }
    DEF FIRST_LEFT_WHEEL HingeJoint {
      jointParameters HingeJointParameters {
        position -9597.877033673038
        axis 0 -1 0
        anchor 0.049 0.0394 0.014
      }
      device [
        RotationalMotor {
          name "wheel_motor00"
          maxVelocity 50
        }
        PositionSensor {
          name "wheel_sensor00"
        }
      ]
      endPoint Solid {
        translation 0.049 0.0394 0.014
        rotation 0 -0.9999999999999999 0 2.8301156973704784
        name "first left wheel"
        contactMaterial "wheel"
        boundingObject DEF BOUNDING_WHEEL Pose {
          rotation 1 0 0 -1.57
          children [
            Cylinder {
              height 0.0198
              radius 0.014
            }
          ]
        }
        physics DEF PHYSICS_FRONT_WHEEL Physics {
          density -1
          mass 0.005
        }
      }
    }
    DEF SECOND_LEFT_WHEEL HingeJoint {
      jointParameters HingeJointParameters {
        position -7649.041629830484
        axis 0 -1 0
        anchor 0.0245 0.0394 0.014
      }
      device [
        RotationalMotor {
          name "wheel_motor01"
          maxVelocity 50
        }
        PositionSensor {
          name "wheel_sensor01"
        }
      ]
      endPoint Solid {
        translation 0.0245 0.0394 0.014
        rotation 0 -0.9999999999999999 0 3.878074314251876
        name "second left wheel"
        contactMaterial "wheel"
        boundingObject USE BOUNDING_WHEEL
        physics USE PHYSICS_FRONT_WHEEL
      }
    }
    DEF THIRD_LEFT_WHEEL HingeJoint {
      jointParameters HingeJointParameters {
        position -9570.838446196438
        axis 0 -1 0
        anchor 0 0.0394 0.014
      }
      device [
        RotationalMotor {
          name "wheel_motor02"
          maxVelocity 50
        }
        PositionSensor {
          name "wheel_sensor02"
        }
      ]
      endPoint Solid {
        translation 0 0.0394 0.014
        rotation 0 -0.9999999999999999 0 4.735961945251919
        name "third left wheel"
        contactMaterial "center_wheel"
        boundingObject USE BOUNDING_WHEEL
        physics DEF PHYSICS_CENTER_WHEEL Physics {
          density -1
          mass 0.005
        }
      }
    }
    DEF FOURTH_LEFT_WHEEL HingeJoint {
      jointParameters HingeJointParameters {
        position -9570.838455447849
        axis 0 -1 0
        anchor -0.0245 0.0394 0.014
      }
      device [
        RotationalMotor {
          name "wheel_motor03"
          maxVelocity 50
        }
        PositionSensor {
          name "wheel_sensor03"
        }
      ]
      endPoint Solid {
        translation -0.0245 0.0394 0.014
        rotation 0 -1 0 4.73595269384089
        name "fourth left wheel"
        contactMaterial "wheel"
        boundingObject USE BOUNDING_WHEEL
        physics USE PHYSICS_FRONT_WHEEL
      }
    }
    DEF LAST_LEFT_WHEEL HingeJoint {
      jointParameters HingeJointParameters {
        position -9570.838446135767
        axis 0 -1 0
        anchor -0.049 0.0394 0.014
      }
      device [
        RotationalMotor {
          name "wheel_motor04"
          maxVelocity 50
        }
        PositionSensor {
          name "wheel_sensor04"
        }
      ]
      endPoint Solid {
        translation -0.049 0.0394 0.014
        rotation 0 -1 0 4.735962005922492
        name "last left wheel"
        contactMaterial "wheel"
        boundingObject USE BOUNDING_WHEEL
        physics USE PHYSICS_FRONT_WHEEL
      }
    }
    DEF FIRST_RIGHT_WHEEL HingeJoint {
      jointParameters HingeJointParameters {
        position -9691.207934757702
        axis 0 -1 0
        anchor 0.049 -0.0394 0.014
      }
      device [
        RotationalMotor {
          name "wheel_motor05"
          maxVelocity 50
        }
        PositionSensor {
          name "wheel_sensor05"
        }
      ]
      endPoint Solid {
        translation 0.049 -0.0394 0.014
        rotation 0 1 0 2.5361910867795308
        name "first right wheel"
        contactMaterial "wheel"
        boundingObject USE BOUNDING_WHEEL
        physics USE PHYSICS_FRONT_WHEEL
      }
    }
    DEF SECOND_RIGHT_WHEEL HingeJoint {
      jointParameters HingeJointParameters {
        position -9691.207934616661
        axis 0 -1 0
        anchor 0.0245 -0.0394 0.014
      }
      device [
        RotationalMotor {
          name "wheel_motor06"
          maxVelocity 50
        }
        PositionSensor {
          name "wheel_sensor06"
        }
      ]
      endPoint Solid {
        translation 0.0245 -0.0394 0.014
        rotation 0 1 0 2.5361909457387304
        name "second right wheel"
        contactMaterial "wheel"
        boundingObject USE BOUNDING_WHEEL
        physics USE PHYSICS_FRONT_WHEEL
      }
    }
    DEF THIRD_RIGHT_WHEEL HingeJoint {
      jointParameters HingeJointParameters {
        position -9691.207943221716
        axis 0 -1 0
        anchor 0 -0.0394 0.014
      }
      device [
        RotationalMotor {
          name "wheel_motor07"
          maxVelocity 50
        }
        PositionSensor {
          name "wheel_sensor07"
        }
      ]
      endPoint Solid {
        translation 0 -0.0394 0.014
        rotation 0 1 0 2.536199550793703
        name "third right wheel"
        contactMaterial "center_wheel"
        boundingObject USE BOUNDING_WHEEL
        physics USE PHYSICS_CENTER_WHEEL
      }
    }
    DEF FOURTH_RIGHT_WHEEL HingeJoint {
      jointParameters HingeJointParameters {
        position -9691.2079550895
        axis 0 -1 0
        anchor -0.0245 -0.0394 0.014
      }
      device [
        RotationalMotor {
          name "wheel_motor08"
          maxVelocity 50
        }
        PositionSensor {
          name "wheel_sensor08"
        }
      ]
      endPoint Solid {
        translation -0.0245 -0.0394 0.014
        rotation 0 1 0 2.5362114185772446
        name "forth right wheel"
        contactMaterial "wheel"
        boundingObject USE BOUNDING_WHEEL
        physics USE PHYSICS_FRONT_WHEEL
      }
    }
    DEF LAST_RIGHT_WHEEL HingeJoint {
      jointParameters HingeJointParameters {
        position -9691.20795171104
        axis 0 -1 0
        anchor -0.049 -0.0394 0.014
      }
      device [
        RotationalMotor {
          name "wheel_motor09"
          maxVelocity 50
        }
        PositionSensor {
          name "wheel_sensor09"
        }
      ]
      endPoint Solid {
        translation -0.049 -0.0394 0.014
        rotation 0 1 0 2.5362080401172937
        name "last right wheel"
        contactMaterial "wheel"
        boundingObject USE BOUNDING_WHEEL
        physics USE PHYSICS_FRONT_WHEEL
      }
    }
  ]
  name "Alphie(1)"
  model "Alphie'sModel"
  description "Simulation of the real robot Alphie"
  boundingObject Group {
    children [
      Pose {
        translation 0 0 0.04
        children [
          Box {
            size 0.125 0.1 0.07
          }
        ]
      }
    ]
  }
  physics Physics {
    density -1
    mass 0.324
    centerOfMass [
      -0.005 0 0.028
    ]
    inertiaMatrix [
      0.000267079 0.000473553 0.000418585
      0 -6.02166e-06 0
    ]
  }
  controller "MainController"
}
Robot {
  translation 1.4113013861267905 -0.5475361722956573 -3.211358593260133e-05
  rotation -6.925583131867286e-05 5.8847862518202837e-05 0.9999999958702794 1.3931820007934586
  children [
    Group {
    }
    DEF BODY Group {
      children [
        DEF LEFT_TRACK Pose {
          translation 0 0.0295 0.014
          rotation 1 0 0 -1.57
          children [
            DEF TRACK Group {
              children [
                Pose {
                  translation -0.049 0 0
                  children [
                    DEF TRACK_EXTRUSION Shape {
                      appearance DEF BLACK PBRAppearance {
                        baseColor 0 0 0
                        roughness 0.7
                        metalness 0
                      }
                      geometry IndexedFaceSet {
                        coord Coordinate {
                          point [
                            0 0.014 0
                            -0.007 0.01212 0
                            -0.01212 0.007 0
                            -0.014 0 0
                            -0.01212 -0.007 0
                            -0.007 -0.01212 0
                            0 -0.014 0
                            0 0.014 0
                            0 0.014 0.0198
                            -0.007 0.01212 0.0198
                            -0.01212 0.007 0.0198
                            -0.014 0 0.0198
                            -0.01212 -0.007 0.0198
                            -0.007 -0.01212 0.0198
                            0 -0.014 0.0198
                            0 0.014 0.0198
                          ]
                        }
                        coordIndex [
                          7, 6, 5, 4, 3, 2, 1, 0, -1, 8, 9, 10, 11, 12, 13, 14, 15, -1, 0, 1, 9, 8, -1, 1, 2, 10, 9, -1, 2, 3, 11, 10, -1, 3, 4, 12, 11, -1, 4, 5, 13, 12, -1, 5, 6, 14, 13, -1, 6, 7, 15, 14, -1
                        ]
                      }
                    }
                  ]
                }
                Pose {
                  translation 0.049 0 0
                  rotation 0 0 1 3.14
                  children [
                    DEF TRACK_EXTRUSION Shape {
                      appearance USE BLACK
                      geometry IndexedFaceSet {
                        coord Coordinate {
                          point [
                            0 0.014 0
                            -0.007 0.01212 0
                            -0.01212 0.007 0
                            -0.014 0 0
                            -0.01212 -0.007 0
                            -0.007 -0.01212 0
                            0 -0.014 0
                            0 0.014 0
                            0 0.014 0.0198
                            -0.007 0.01212 0.0198
                            -0.01212 0.007 0.0198
                            -0.014 0 0.0198
                            -0.01212 -0.007 0.0198
                            -0.007 -0.01212 0.0198
                            0 -0.014 0.0198
                            0 0.014 0.0198
                          ]
                        }
                        coordIndex [
                          7, 6, 5, 4, 3, 2, 1, 0, -1, 8, 9, 10, 11, 12, 13, 14, 15, -1, 0, 1, 9, 8, -1, 1, 2, 10, 9, -1, 2, 3, 11, 10, -1, 3, 4, 12, 11, -1, 4, 5, 13, 12, -1, 5, 6, 14, 13, -1, 6, 7, 15, 14, -1
                        ]
                      }
                    }
                  ]
                }
                Pose {
                  translation 0.049 0 0.0101
                  children [
                    DEF TRACK_WHEEL Shape {
                      appearance DEF GRAY PBRAppearance {
                        roughness 0.2
                      }
                      geometry Cylinder {
                        height 0.0205
                        radius 0.011
                      }
                    }
                  ]
                }
                Pose {
                  translation -0.049 0 0.0101
                  children [
                    USE TRACK_WHEEL
                  ]
                }
                Pose {
                  translation 0 -0.0125 0.0099
                  children [
                    DEF TRACK_BOX Shape {
                      appearance USE BLACK
                      geometry Box {
                        size 0.098 0.003 0.0198
                      }
                    }
                  ]
                }
                Pose {
                  translation 0 0.0125 0.0099
                  children [
                    USE TRACK_BOX
                  ]
                }
              ]
            }
          ]
        }
        DEF RIGHT_TRACK Pose {
          translation 0 -0.0295 0.014
          rotation 1 0 0 1.57
          children [
            USE TRACK
          ]
        }
        DEF BASE Pose {
          translation 0 0 0.014
          children [
            Pose {
              translation -0.056 -5.91374e-08 0.02
              rotation 0 0 1 -1.5707953071795862
              children [
                Shape {
                  appearance PBRAppearance {
                    baseColor 0 0 0
                    roughness 1
                    metalness 0
                  }
                  geometry Box {
                    size 0.055 0.001 0.021
                  }
                }
              ]
              translationStep 0.001
            }
            Pose {
              translation -0.0182 0.026 0.014
              children [
                Shape {
                  appearance PBRAppearance {
                    baseColor 0 0 0
                    roughness 1
                    metalness 0
                  }
                  geometry Box {
                    size 0.075 0.001 0.034
                  }
                }
              ]
              translationStep 0.0001
            }
            Pose {
              translation -0.019 -0.0266 0.0145
              children [
                Shape {
                  appearance PBRAppearance {
                    baseColor 0 0 0
                    roughness 1
                    metalness 0
                  }
                  geometry Box {
                    size 0.075 0.001 0.034
                  }
                }
              ]
              translationStep 0.0001
            }
            Pose {
              translation -0.0466 -0.016 0.00562
              rotation 1 0 0 1.57
              children [
                DEF WHEEL_AXE Shape {
                  appearance PBRAppearance {
                    baseColor 0.392157 0.392157 0.392157
                    roughness 1
                    metalness 0
                  }
                  geometry Cylinder {
                    height 0.02
                    radius 0.0035
                  }
                }
              ]
              translationStep 0.0001
            }
            Pose {
              translation -0.0466 0.0159912 0.00562
              rotation 1 0 0 1.57
              children [
                USE WHEEL_AXE
              ]
              translationStep 0.001
            }
          ]
        }
        DEF FRONT_SUPPORT Pose {
          translation 0.0754 0 0.021
          children [
            DEF Composant Group {
              children [
                DEF ANTENNEGPS Pose {
                  translation -0.0427 -0.012 0.0118
                  children [
                    Solid {
                      translation 0 0 0.0312
                      children [
                        TrafficCone {
                          scale 0.03
                        }
                      ]
                      name "GPSComposant"
                      translationStep 0.0001
                    }
                    Solid {
                      translation 0 0 0.0314
                      children [
                        Shape {
                          appearance FlexibleAluminiumDuct {
                          }
                          geometry Cylinder {
                            height 0.0005
                            radius 0.02
                          }
                        }
                      ]
                      name "plaqueMetal"
                      translationStep 0.0001
                    }
                    Solid {
                      translation 0 0 0.0168
                      children [
                        Shape {
                          appearance PBRAppearance {
                            baseColor 1 0 0
                            roughness 1
                          }
                          geometry Cylinder {
                            height 0.03
                            radius 0.006
                          }
                        }
                      ]
                      name "colonne"
                      translationStep 0.0001
                    }
                    Shape {
                      appearance PBRAppearance {
                        baseColor 1 0 0
                        roughness 1
                      }
                      geometry Box {
                        size 0.026 0.023 0.003
                      }
                    }
                  ]
                  translationStep 0.0001
                }
                DEF CARTEMOTEUR Pose {
                  translation -0.1059 0.0112 0.0276
                  children [
                    Shape {
                      appearance PBRAppearance {
                        baseColorMap ImageTexture {
                          url [
                            "../pictures/carte_moteur.png"
                          ]
                        }
                        roughnessMap ImageTexture {
                        }
                        metalness 0
                        metalnessMap ImageTexture {
                          url [
                            "https://raw.githubusercontent.com/cyberbotics/webots/R2023b/projects/robots/surveyor/protos/textures/surveyor_serial_metalness.jpg"
                          ]
                        }
                        normalMap ImageTexture {
                          url [
                            "https://raw.githubusercontent.com/cyberbotics/webots/R2023b/projects/robots/surveyor/protos/textures/surveyor_serial_normal.jpg"
                          ]
                        }
                      }
                      geometry IndexedFaceSet {
                        coord Coordinate {
                          point [
                            0.017 -0.015 0.0031
                            -0.019 -0.015 0.0031
                            -0.019 0.015 0.0031
                            0.017 0.0145 0.0031
                          ]
                        }
                        texCoord TextureCoordinate {
                          point [
                            0 0
                            1 0
                            1 1
                            0 1
                          ]
                        }
                        coordIndex [
                          0, 3, 2, 1, -1
                        ]
                        texCoordIndex [
                          0, 1, 2, 3, -1
                        ]
                      }
                    }
                    Shape {
                      appearance USE BLACK
                      geometry Box {
                        size 0.031 0.028 0.006
                      }
                    }
                  ]
                  translationStep 0.0001
                }
                DEF BREADBOARD Pose {
                  translation -0.0718 0.0177 0.0274
                  children [
                    Shape {
                      appearance PBRAppearance {
                        baseColorMap ImageTexture {
                          url [
                            "../pictures/breadboard.jpg"
                          ]
                        }
                        roughnessMap ImageTexture {
                          url [
                            "https://raw.githubusercontent.com/cyberbotics/webots/R2023b/projects/robots/surveyor/protos/textures/surveyor_serial_roughness.jpg"
                          ]
                        }
                        metalness 0
                        metalnessMap ImageTexture {
                          url [
                            "https://raw.githubusercontent.com/cyberbotics/webots/R2023b/projects/robots/surveyor/protos/textures/surveyor_serial_metalness.jpg"
                          ]
                        }
                        normalMap ImageTexture {
                          url [
                            "https://raw.githubusercontent.com/cyberbotics/webots/R2023b/projects/robots/surveyor/protos/textures/surveyor_serial_normal.jpg"
                          ]
                        }
                      }
                      geometry IndexedFaceSet {
                        coord Coordinate {
                          point [
                            0.0105 0.0075 0.00251
                            0.0105 -0.0075 0.00251
                            -0.0105 -0.0072 0.00251
                            -0.0105 0.0072 0.00251
                          ]
                        }
                        texCoord TextureCoordinate {
                          point [
                            0 0
                            1 0
                            1 1
                            0 1
                          ]
                        }
                        coordIndex [
                          0, 3, 2, 1, -1
                        ]
                        texCoordIndex [
                          0, 1, 2, 3, -1
                        ]
                      }
                    }
                    Shape {
                      appearance PBRAppearance {
                        baseColor 0.870588 0.870588 0.870588
                        roughness 1
                        metalness 0
                      }
                      geometry Box {
                        size 0.021 0.015 0.005
                      }
                    }
                  ]
                  translationStep 0.0001
                }
                DEF RADIO Pose {
                  translation -0.0344 0.0118 0.013
                  rotation 0 0 1 3.14159
                  children [
                    Shape {
                      appearance PBRAppearance {
                        baseColorMap ImageTexture {
                          url [
                            "../pictures/ModuleRadio.png"
                          ]
                        }
                        roughnessMap ImageTexture {
                          url [
                            "https://raw.githubusercontent.com/cyberbotics/webots/R2023b/projects/robots/surveyor/protos/textures/surveyor_serial_roughness.jpg"
                          ]
                        }
                        metalnessMap ImageTexture {
                          url [
                            "https://raw.githubusercontent.com/cyberbotics/webots/R2023b/projects/robots/surveyor/protos/textures/surveyor_serial_metalness.jpg"
                          ]
                        }
                        normalMap ImageTexture {
                          url [
                            "https://raw.githubusercontent.com/cyberbotics/webots/R2023b/projects/robots/surveyor/protos/textures/surveyor_serial_normal.jpg"
                          ]
                        }
                      }
                      geometry IndexedFaceSet {
                        coord Coordinate {
                          point [
                            0.01 -0.0035 0.0016
                            -0.01 -0.0035 0.0016
                            -0.01 0.0035 0.0016
                            0.01 0.0035 0.0016
                          ]
                        }
                        texCoord TextureCoordinate {
                          point [
                            0 0
                            1 0
                            1 1
                            0 1
                          ]
                        }
                        coordIndex [
                          0, 3, 2, 1, -1
                        ]
                        texCoordIndex [
                          0, 1, 2, 3, -1
                        ]
                      }
                    }
                    Shape {
                      appearance USE BLACK
                      geometry Box {
                        size 0.02 0.007 0.003
                      }
                    }
                  ]
                  translationStep 0.0001
                }
                DEF ARDUINOR4 Pose {
                  translation -0.1044 -0.0158 0.0264
                  children [
                    Shape {
                      appearance PBRAppearance {
                        baseColorMap ImageTexture {
                          url [
                            "../pictures/UnoR4Wifi.png"
                          ]
                          filtering 3
                        }
                        roughnessMap ImageTexture {
                          url [
                            "https://raw.githubusercontent.com/cyberbotics/webots/R2023b/projects/robots/surveyor/protos/textures/surveyor_serial_roughness.jpg"
                          ]
                        }
                        metalness 0
                        metalnessMap ImageTexture {
                          url [
                            "https://raw.githubusercontent.com/cyberbotics/webots/R2023b/projects/robots/surveyor/protos/textures/surveyor_serial_metalness.jpg"
                          ]
                        }
                        normalMap ImageTexture {
                          url [
                            "https://raw.githubusercontent.com/cyberbotics/webots/R2023b/projects/robots/surveyor/protos/textures/surveyor_serial_normal.jpg"
                          ]
                        }
                      }
                      geometry IndexedFaceSet {
                        coord Coordinate {
                          point [
                            -0.0184 -0.01 0.00151
                            -0.0183 0.01 0.00151
                            0.0185 0.01 0.00151
                            0.0185 -0.01 0.00151
                          ]
                        }
                        texCoord TextureCoordinate {
                          point [
                            0 0
                            1 0
                            1 1
                            0 1
                          ]
                        }
                        coordIndex [
                          0, 3, 2, 1, -1
                        ]
                        texCoordIndex [
                          0, 1, 2, 3, -1
                        ]
                      }
                    }
                    Shape {
                      appearance USE BLACK
                      geometry Box {
                        size 0.037 0.02 0.003
                      }
                    }
                  ]
                }
              ]
            }
            DEF SUPPORT Group {
              children [
                Pose {
                  translation -0.0364 0 -0.004
                  children [
                    Shape {
                      appearance DEF BlackRobotAlphie PBRAppearance {
                        baseColor 0 0 0
                        roughness 1
                        metalness 0
                        name ""
                      }
                      geometry Box {
                        size 0.04 0.0525 0.0011
                      }
                    }
                  ]
                  translationStep 0.001
                }
                Pose {
                  translation -0.0433 0 0.0102
                  children [
                    Shape {
                      appearance DEF BlackRobotAlphie PBRAppearance {
                        baseColor 0 0 0
                        roughness 1
                        metalness 0
                        name ""
                      }
                      geometry Box {
                        size 0.03 0.0525 0.0011
                      }
                    }
                  ]
                  translationStep 0.0001
                }
                Shape {
                  appearance PBRAppearance {
                    baseColor 0.85098 0.85098 0.85098
                    baseColorMap ImageTexture {
                      url [
                        "../pictures/FrontAlphie.png"
                      ]
                      repeatS FALSE
                      repeatT FALSE
                    }
                    roughness 1
                    roughnessMap ImageTexture {
                      url [
                        "https://raw.githubusercontent.com/cyberbotics/webots/R2023b/projects/robots/surveyor/protos/textures/surveyor_top_roughness.jpg"
                      ]
                    }
                    metalness 0
                    metalnessMap ImageTexture {
                      url [
                        "https://raw.githubusercontent.com/cyberbotics/webots/R2023b/projects/robots/surveyor/protos/textures/surveyor_top_metalness.jpg"
                      ]
                    }
                    normalMap ImageTexture {
                      url [
                        "https://raw.githubusercontent.com/cyberbotics/webots/R2023b/projects/robots/surveyor/protos/textures/surveyor_top_normal.jpg"
                      ]
                    }
                  }
                  geometry IndexedFaceSet {
                    coord Coordinate {
                      point [
                        -0.059 0.026 0.011
                        -0.028 0.026 0.011
                        -0.028 -0.026 0.011
                        -0.059 -0.026 0.011
                      ]
                    }
                    texCoord TextureCoordinate {
                      point [
                        0 0
                        1 0
                        1 1
                        0 1
                      ]
                    }
                    coordIndex [
                      0, 3, 2, 1, -1
                    ]
                    texCoordIndex [
                      0, 1, 2, 3, -1
                    ]
                  }
                }
                Pose {
                  translation -0.0227073 3.05188e-07 0.00330141
                  rotation -0.6848107156457631 0.6848157156436869 -0.2491218965570118 2.65328
                  children [
                    Shape {
                      appearance USE BlackRobotAlphie
                      geometry Box {
                        size 0.0525 0.0012 0.0185
                      }
                    }
                  ]
                  translationStep 0.0001
                }
              ]
            }
          ]
        }
        DEF TOP_PLATE Group {
          children [
            Pose {
              translation -0.0186 0 0.0449
              children [
                Shape {
                  appearance PBRAppearance {
                    baseColor 0 0 0
                    roughness 1
                    metalness 0
                  }
                  geometry Box {
                    size 0.076 0.053 0.0015
                  }
                }
              ]
              translationStep 0.001
            }
            DEF TOP Pose {
              translation -0.006 -6.36861e-08 0.0477
              rotation 0 0 1 3.14159
              children [
                GPS {
                  rotation 0 0 1 3.14159
                }
                Compass {
                  rotation 0 0 1 3.14159
                }
                Shape {
                  appearance PBRAppearance {
                    baseColorMap ImageTexture {
                      url [
                        "../pictures/TopAlphie.png"
                      ]
                      repeatS FALSE
                      repeatT FALSE
                    }
                    roughness 1
                    roughnessMap ImageTexture {
                      url [
                        "https://raw.githubusercontent.com/cyberbotics/webots/R2023b/projects/robots/surveyor/protos/textures/surveyor_top_roughness.jpg"
                      ]
                    }
                    metalness 0
                    metalnessMap ImageTexture {
                      url [
                        "https://raw.githubusercontent.com/cyberbotics/webots/R2023b/projects/robots/surveyor/protos/textures/surveyor_top_metalness.jpg"
                      ]
                    }
                    normalMap ImageTexture {
                      url [
                        "https://raw.githubusercontent.com/cyberbotics/webots/R2023b/projects/robots/surveyor/protos/textures/surveyor_top_normal.jpg"
                      ]
                    }
                  }
                  geometry IndexedFaceSet {
                    coord Coordinate {
                      point [
                        0.05 -0.027 -0.002
                        -0.026 -0.027 -0.002
                        -0.026 0.027 -0.002
                        0.05 0.027 -0.002
                      ]
                    }
                    texCoord TextureCoordinate {
                      point [
                        0 0
                        1 0
                        1 1
                        0 1
                      ]
                    }
                    coordIndex [
                      0, 3, 2, 1, -1
                    ]
                    texCoordIndex [
                      0, 1, 2, 3, -1
                    ]
                  }
                }
              ]
              translationStep 0.001
            }
          ]
        }
        DEF BATTERIES Group {
          children [
            Pose {
              translation -0.0220079 -5.51926e-08 0.0270237
              rotation 0.577656895078166 -0.5771968951617173 0.5771968951617173 2.09394
              children [
                DEF BATTERY Shape {
                  appearance DEF BlackRobot PBRAppearance {
                    baseColor 0.360784 0.360784 0.360784
                    roughness 1
                    metalness 0
                  }
                  geometry Box {
                    size 0.015 0.02 0.05
                  }
                }
              ]
            }
          ]
        }
      ]
    }
    DEF ANTENNA_EMITTER Emitter {
      translation 0.0451 0.0118 0.037
      children [
        DEF RangeEmitter Shape {
          appearance PBRAppearance {
            baseColor 1 0 0
            transparency 0.8
            roughness 1
            metalness 0
          }
          geometry Sphere {
            radius 1.5
            subdivision 5
          }
        }
        Pose {
          translation 0 0 -0.008
          children [
            Shape {
              appearance USE BLACK
              geometry Cylinder {
                height 0.019
                radius 0.0006
              }
            }
          ]
        }
        Pose {
          children [
            Shape {
              appearance USE BLACK
              geometry Cylinder {
                height 0.007
                radius 0.0015
              }
            }
          ]
        }
      ]
      translationStep 0.0001
      range 1.5
    }
    DEF ANTENNA_RECEIVER Receiver {
      translation 0.0451 0.0118 0.037
    }
    DEF FIRST_LEFT_WHEEL HingeJoint {
      jointParameters HingeJointParameters {
        position -8994.666776308692
        axis 0 -1 0
        anchor 0.049 0.0394 0.014
      }
      device [
        RotationalMotor {
          name "wheel_motor00"
          maxVelocity 50
        }
        PositionSensor {
          name "wheel_sensor00"
        }
      ]
      endPoint Solid {
        translation 0.049 0.0394 0.014
        rotation 0 -1 0 2.854583572476211
        name "first left wheel"
        contactMaterial "wheel"
        boundingObject DEF BOUNDING_WHEEL Pose {
          rotation 1 0 0 -1.57
          children [
            Cylinder {
              height 0.0198
              radius 0.014
            }
          ]
        }
        physics DEF PHYSICS_FRONT_WHEEL Physics {
          density -1
          mass 0.005
        }
      }
    }
    DEF SECOND_LEFT_WHEEL HingeJoint {
      jointParameters HingeJointParameters {
        position -7045.831371699441
        axis 0 -1 0
        anchor 0.0245 0.0394 0.014
      }
      device [
        RotationalMotor {
          name "wheel_motor01"
          maxVelocity 50
        }
        PositionSensor {
          name "wheel_sensor01"
        }
      ]
      endPoint Solid {
        translation 0.0245 0.0394 0.014
        rotation 0 -1 0 3.902542956055276
        name "second left wheel"
        contactMaterial "wheel"
        boundingObject USE BOUNDING_WHEEL
        physics USE PHYSICS_FRONT_WHEEL
      }
    }
    DEF THIRD_LEFT_WHEEL HingeJoint {
      jointParameters HingeJointParameters {
        position -8967.62818807417
        axis 0 -1 0
        anchor 0 0.0394 0.014
      }
      device [
        RotationalMotor {
          name "wheel_motor02"
          maxVelocity 50
        }
        PositionSensor {
          name "wheel_sensor02"
        }
      ]
      endPoint Solid {
        translation 0 0.0394 0.014
        rotation 0 -1 0 4.760430578279605
        name "third left wheel"
        contactMaterial "center_wheel"
        boundingObject USE BOUNDING_WHEEL
        physics DEF PHYSICS_CENTER_WHEEL Physics {
          density -1
          mass 0.005
        }
      }
    }
    DEF FOURTH_LEFT_WHEEL HingeJoint {
      jointParameters HingeJointParameters {
        position -8967.628197557275
        axis 0 -1 0
        anchor -0.0245 0.0394 0.014
      }
      device [
        RotationalMotor {
          name "wheel_motor03"
          maxVelocity 50
        }
        PositionSensor {
          name "wheel_sensor03"
        }
      ]
      endPoint Solid {
        translation -0.0245 0.0394 0.014
        rotation 0 -1 0 4.7604210951748005
        name "fourth left wheel"
        contactMaterial "wheel"
        boundingObject USE BOUNDING_WHEEL
        physics USE PHYSICS_FRONT_WHEEL
      }
    }
    DEF LAST_LEFT_WHEEL HingeJoint {
      jointParameters HingeJointParameters {
        position -8967.628184978805
        axis 0 -1 0
        anchor -0.049 0.0394 0.014
      }
      device [
        RotationalMotor {
          name "wheel_motor04"
          maxVelocity 50
        }
        PositionSensor {
          name "wheel_sensor04"
        }
      ]
      endPoint Solid {
        translation -0.049 0.0394 0.014
        rotation 0 -1 0 4.760433673644778
        name "last left wheel"
        contactMaterial "wheel"
        boundingObject USE BOUNDING_WHEEL
        physics USE PHYSICS_FRONT_WHEEL
      }
    }
    DEF FIRST_RIGHT_WHEEL HingeJoint {
      jointParameters HingeJointParameters {
        position -9119.851606788498
        axis 0 -1 0
        anchor 0.049 -0.0394 0.014
      }
      device [
        RotationalMotor {
          name "wheel_motor05"
          maxVelocity 50
        }
        PositionSensor {
          name "wheel_sensor05"
        }
      ]
      endPoint Solid {
        translation 0.049 -0.0394 0.014
        rotation 0 -1 0 3.3334592362620445
        name "first right wheel"
        contactMaterial "wheel"
        boundingObject USE BOUNDING_WHEEL
        physics USE PHYSICS_FRONT_WHEEL
      }
    }
    DEF SECOND_RIGHT_WHEEL HingeJoint {
      jointParameters HingeJointParameters {
        position -9119.851606231581
        axis 0 -1 0
        anchor 0.0245 -0.0394 0.014
      }
      device [
        RotationalMotor {
          name "wheel_motor06"
          maxVelocity 50
        }
        PositionSensor {
          name "wheel_sensor06"
        }
      ]
      endPoint Solid {
        translation 0.0245 -0.0394 0.014
        rotation 0 -1 0 3.3334597931783922
        name "second right wheel"
        contactMaterial "wheel"
        boundingObject USE BOUNDING_WHEEL
        physics USE PHYSICS_FRONT_WHEEL
      }
    }
    DEF THIRD_RIGHT_WHEEL HingeJoint {
      jointParameters HingeJointParameters {
        position -9119.851614544254
        axis 0 -1 0
        anchor 0 -0.0394 0.014
      }
      device [
        RotationalMotor {
          name "wheel_motor07"
          maxVelocity 50
        }
        PositionSensor {
          name "wheel_sensor07"
        }
      ]
      endPoint Solid {
        translation 0 -0.0394 0.014
        rotation 0 -1 0 3.3334514805059574
        name "third right wheel"
        contactMaterial "center_wheel"
        boundingObject USE BOUNDING_WHEEL
        physics USE PHYSICS_CENTER_WHEEL
      }
    }
    DEF FOURTH_RIGHT_WHEEL HingeJoint {
      jointParameters HingeJointParameters {
        position -9119.851626646177
        axis 0 -1 0
        anchor -0.0245 -0.0394 0.014
      }
      device [
        RotationalMotor {
          name "wheel_motor08"
          maxVelocity 50
        }
        PositionSensor {
          name "wheel_sensor08"
        }
      ]
      endPoint Solid {
        translation -0.0245 -0.0394 0.014
        rotation 0 -1 0 3.3334393785820997
        name "forth right wheel"
        contactMaterial "wheel"
        boundingObject USE BOUNDING_WHEEL
        physics USE PHYSICS_FRONT_WHEEL
      }
    }
    DEF LAST_RIGHT_WHEEL HingeJoint {
      jointParameters HingeJointParameters {
        position -9119.85162297675
        axis 0 -1 0
        anchor -0.049 -0.0394 0.014
      }
      device [
        RotationalMotor {
          name "wheel_motor09"
          maxVelocity 50
        }
        PositionSensor {
          name "wheel_sensor09"
        }
      ]
      endPoint Solid {
        translation -0.049 -0.0394 0.014
        rotation 0 -0.9999999999999999 0 3.3334430480094146
        name "last right wheel"
        contactMaterial "wheel"
        boundingObject USE BOUNDING_WHEEL
        physics USE PHYSICS_FRONT_WHEEL
      }
    }
  ]
  name "Alphie(2)"
  model "Alphie'sModel"
  description "Simulation of the real robot Alphie"
  boundingObject Group {
    children [
      Pose {
        translation 0 0 0.04
        children [
          Box {
            size 0.125 0.1 0.07
          }
        ]
      }
    ]
  }
  physics Physics {
    density -1
    mass 0.324
    centerOfMass [
      -0.005 0 0.028
    ]
    inertiaMatrix [
      0.000267079 0.000473553 0.000418585
      0 -6.02166e-06 0
    ]
  }
  controller "MainController"
}
Robot {
  translation 1.44127 0.229758 0.000474332
  rotation 0.0002923632724008731 -0.00026560418593800275 0.9999999219890636 1.5661443898782044
  children [
    Group {
    }
    DEF BODY Group {
      children [
        DEF LEFT_TRACK Pose {
          translation 0 0.0295 0.014
          rotation 1 0 0 -1.57
          children [
            DEF TRACK Group {
              children [
                Pose {
                  translation -0.049 0 0
                  children [
                    DEF TRACK_EXTRUSION Shape {
                      appearance DEF BLACK PBRAppearance {
                        baseColor 0 0 0
                        roughness 0.7
                        metalness 0
                      }
                      geometry IndexedFaceSet {
                        coord Coordinate {
                          point [
                            0 0.014 0
                            -0.007 0.01212 0
                            -0.01212 0.007 0
                            -0.014 0 0
                            -0.01212 -0.007 0
                            -0.007 -0.01212 0
                            0 -0.014 0
                            0 0.014 0
                            0 0.014 0.0198
                            -0.007 0.01212 0.0198
                            -0.01212 0.007 0.0198
                            -0.014 0 0.0198
                            -0.01212 -0.007 0.0198
                            -0.007 -0.01212 0.0198
                            0 -0.014 0.0198
                            0 0.014 0.0198
                          ]
                        }
                        coordIndex [
                          7, 6, 5, 4, 3, 2, 1, 0, -1, 8, 9, 10, 11, 12, 13, 14, 15, -1, 0, 1, 9, 8, -1, 1, 2, 10, 9, -1, 2, 3, 11, 10, -1, 3, 4, 12, 11, -1, 4, 5, 13, 12, -1, 5, 6, 14, 13, -1, 6, 7, 15, 14, -1
                        ]
                      }
                    }
                  ]
                }
                Pose {
                  translation 0.049 0 0
                  rotation 0 0 1 3.14
                  children [
                    DEF TRACK_EXTRUSION Shape {
                      appearance USE BLACK
                      geometry IndexedFaceSet {
                        coord Coordinate {
                          point [
                            0 0.014 0
                            -0.007 0.01212 0
                            -0.01212 0.007 0
                            -0.014 0 0
                            -0.01212 -0.007 0
                            -0.007 -0.01212 0
                            0 -0.014 0
                            0 0.014 0
                            0 0.014 0.0198
                            -0.007 0.01212 0.0198
                            -0.01212 0.007 0.0198
                            -0.014 0 0.0198
                            -0.01212 -0.007 0.0198
                            -0.007 -0.01212 0.0198
                            0 -0.014 0.0198
                            0 0.014 0.0198
                          ]
                        }
                        coordIndex [
                          7, 6, 5, 4, 3, 2, 1, 0, -1, 8, 9, 10, 11, 12, 13, 14, 15, -1, 0, 1, 9, 8, -1, 1, 2, 10, 9, -1, 2, 3, 11, 10, -1, 3, 4, 12, 11, -1, 4, 5, 13, 12, -1, 5, 6, 14, 13, -1, 6, 7, 15, 14, -1
                        ]
                      }
                    }
                  ]
                }
                Pose {
                  translation 0.049 0 0.0101
                  children [
                    DEF TRACK_WHEEL Shape {
                      appearance DEF GRAY PBRAppearance {
                        roughness 0.2
                      }
                      geometry Cylinder {
                        height 0.0205
                        radius 0.011
                      }
                    }
                  ]
                }
                Pose {
                  translation -0.049 0 0.0101
                  children [
                    USE TRACK_WHEEL
                  ]
                }
                Pose {
                  translation 0 -0.0125 0.0099
                  children [
                    DEF TRACK_BOX Shape {
                      appearance USE BLACK
                      geometry Box {
                        size 0.098 0.003 0.0198
                      }
                    }
                  ]
                }
                Pose {
                  translation 0 0.0125 0.0099
                  children [
                    USE TRACK_BOX
                  ]
                }
              ]
            }
          ]
        }
        DEF RIGHT_TRACK Pose {
          translation 0 -0.0295 0.014
          rotation 1 0 0 1.57
          children [
            USE TRACK
          ]
        }
        DEF BASE Pose {
          translation 0 0 0.014
          children [
            Pose {
              translation -0.056 -5.91374e-08 0.02
              rotation 0 0 1 -1.5707953071795862
              children [
                Shape {
                  appearance PBRAppearance {
                    baseColor 0 0 0
                    roughness 1
                    metalness 0
                  }
                  geometry Box {
                    size 0.055 0.001 0.021
                  }
                }
              ]
              translationStep 0.001
            }
            Pose {
              translation -0.0182 0.026 0.014
              children [
                Shape {
                  appearance PBRAppearance {
                    baseColor 0 0 0
                    roughness 1
                    metalness 0
                  }
                  geometry Box {
                    size 0.075 0.001 0.034
                  }
                }
              ]
              translationStep 0.0001
            }
            Pose {
              translation -0.019 -0.0266 0.0145
              children [
                Shape {
                  appearance PBRAppearance {
                    baseColor 0 0 0
                    roughness 1
                    metalness 0
                  }
                  geometry Box {
                    size 0.075 0.001 0.034
                  }
                }
              ]
              translationStep 0.0001
            }
            Pose {
              translation -0.0466 -0.016 0.00562
              rotation 1 0 0 1.57
              children [
                DEF WHEEL_AXE Shape {
                  appearance PBRAppearance {
                    baseColor 0.392157 0.392157 0.392157
                    roughness 1
                    metalness 0
                  }
                  geometry Cylinder {
                    height 0.02
                    radius 0.0035
                  }
                }
              ]
              translationStep 0.0001
            }
            Pose {
              translation -0.0466 0.0159912 0.00562
              rotation 1 0 0 1.57
              children [
                USE WHEEL_AXE
              ]
              translationStep 0.001
            }
          ]
        }
        DEF FRONT_SUPPORT Pose {
          translation 0.0754 0 0.021
          children [
            DEF Composant Group {
              children [
                DEF ANTENNEGPS Pose {
                  translation -0.0427 -0.012 0.0118
                  children [
                    Solid {
                      translation 0 0 0.0312
                      children [
                        TrafficCone {
                          scale 0.03
                        }
                      ]
                      name "GPSComposant"
                      translationStep 0.0001
                    }
                    Solid {
                      translation 0 0 0.0314
                      children [
                        Shape {
                          appearance FlexibleAluminiumDuct {
                          }
                          geometry Cylinder {
                            height 0.0005
                            radius 0.02
                          }
                        }
                      ]
                      name "plaqueMetal"
                      translationStep 0.0001
                    }
                    Solid {
                      translation 0 0 0.0168
                      children [
                        Shape {
                          appearance PBRAppearance {
                            baseColor 1 0 0
                            roughness 1
                          }
                          geometry Cylinder {
                            height 0.03
                            radius 0.006
                          }
                        }
                      ]
                      name "colonne"
                      translationStep 0.0001
                    }
                    Shape {
                      appearance PBRAppearance {
                        baseColor 1 0 0
                        roughness 1
                      }
                      geometry Box {
                        size 0.026 0.023 0.003
                      }
                    }
                  ]
                  translationStep 0.0001
                }
                DEF CARTEMOTEUR Pose {
                  translation -0.1059 0.0112 0.0276
                  children [
                    Shape {
                      appearance PBRAppearance {
                        baseColorMap ImageTexture {
                          url [
                            "../pictures/carte_moteur.png"
                          ]
                        }
                        roughnessMap ImageTexture {
                        }
                        metalness 0
                        metalnessMap ImageTexture {
                          url [
                            "https://raw.githubusercontent.com/cyberbotics/webots/R2023b/projects/robots/surveyor/protos/textures/surveyor_serial_metalness.jpg"
                          ]
                        }
                        normalMap ImageTexture {
                          url [
                            "https://raw.githubusercontent.com/cyberbotics/webots/R2023b/projects/robots/surveyor/protos/textures/surveyor_serial_normal.jpg"
                          ]
                        }
                      }
                      geometry IndexedFaceSet {
                        coord Coordinate {
                          point [
                            0.017 -0.015 0.0031
                            -0.019 -0.015 0.0031
                            -0.019 0.015 0.0031
                            0.017 0.0145 0.0031
                          ]
                        }
                        texCoord TextureCoordinate {
                          point [
                            0 0
                            1 0
                            1 1
                            0 1
                          ]
                        }
                        coordIndex [
                          0, 3, 2, 1, -1
                        ]
                        texCoordIndex [
                          0, 1, 2, 3, -1
                        ]
                      }
                    }
                    Shape {
                      appearance USE BLACK
                      geometry Box {
                        size 0.031 0.028 0.006
                      }
                    }
                  ]
                  translationStep 0.0001
                }
                DEF BREADBOARD Pose {
                  translation -0.0718 0.0177 0.0274
                  children [
                    Shape {
                      appearance PBRAppearance {
                        baseColorMap ImageTexture {
                          url [
                            "../pictures/breadboard.jpg"
                          ]
                        }
                        roughnessMap ImageTexture {
                          url [
                            "https://raw.githubusercontent.com/cyberbotics/webots/R2023b/projects/robots/surveyor/protos/textures/surveyor_serial_roughness.jpg"
                          ]
                        }
                        metalness 0
                        metalnessMap ImageTexture {
                          url [
                            "https://raw.githubusercontent.com/cyberbotics/webots/R2023b/projects/robots/surveyor/protos/textures/surveyor_serial_metalness.jpg"
                          ]
                        }
                        normalMap ImageTexture {
                          url [
                            "https://raw.githubusercontent.com/cyberbotics/webots/R2023b/projects/robots/surveyor/protos/textures/surveyor_serial_normal.jpg"
                          ]
                        }
                      }
                      geometry IndexedFaceSet {
                        coord Coordinate {
                          point [
                            0.0105 0.0075 0.00251
                            0.0105 -0.0075 0.00251
                            -0.0105 -0.0072 0.00251
                            -0.0105 0.0072 0.00251
                          ]
                        }
                        texCoord TextureCoordinate {
                          point [
                            0 0
                            1 0
                            1 1
                            0 1
                          ]
                        }
                        coordIndex [
                          0, 3, 2, 1, -1
                        ]
                        texCoordIndex [
                          0, 1, 2, 3, -1
                        ]
                      }
                    }
                    Shape {
                      appearance PBRAppearance {
                        baseColor 0.870588 0.870588 0.870588
                        roughness 1
                        metalness 0
                      }
                      geometry Box {
                        size 0.021 0.015 0.005
                      }
                    }
                  ]
                  translationStep 0.0001
                }
                DEF RADIO Pose {
                  translation -0.0344 0.0118 0.013
                  rotation 0 0 1 3.14159
                  children [
                    Shape {
                      appearance PBRAppearance {
                        baseColorMap ImageTexture {
                          url [
                            "../pictures/ModuleRadio.png"
                          ]
                        }
                        roughnessMap ImageTexture {
                          url [
                            "https://raw.githubusercontent.com/cyberbotics/webots/R2023b/projects/robots/surveyor/protos/textures/surveyor_serial_roughness.jpg"
                          ]
                        }
                        metalnessMap ImageTexture {
                          url [
                            "https://raw.githubusercontent.com/cyberbotics/webots/R2023b/projects/robots/surveyor/protos/textures/surveyor_serial_metalness.jpg"
                          ]
                        }
                        normalMap ImageTexture {
                          url [
                            "https://raw.githubusercontent.com/cyberbotics/webots/R2023b/projects/robots/surveyor/protos/textures/surveyor_serial_normal.jpg"
                          ]
                        }
                      }
                      geometry IndexedFaceSet {
                        coord Coordinate {
                          point [
                            0.01 -0.0035 0.0016
                            -0.01 -0.0035 0.0016
                            -0.01 0.0035 0.0016
                            0.01 0.0035 0.0016
                          ]
                        }
                        texCoord TextureCoordinate {
                          point [
                            0 0
                            1 0
                            1 1
                            0 1
                          ]
                        }
                        coordIndex [
                          0, 3, 2, 1, -1
                        ]
                        texCoordIndex [
                          0, 1, 2, 3, -1
                        ]
                      }
                    }
                    Shape {
                      appearance USE BLACK
                      geometry Box {
                        size 0.02 0.007 0.003
                      }
                    }
                  ]
                  translationStep 0.0001
                }
                DEF ARDUINOR4 Pose {
                  translation -0.1044 -0.0158 0.0264
                  children [
                    Shape {
                      appearance PBRAppearance {
                        baseColorMap ImageTexture {
                          url [
                            "../pictures/UnoR4Wifi.png"
                          ]
                          filtering 3
                        }
                        roughnessMap ImageTexture {
                          url [
                            "https://raw.githubusercontent.com/cyberbotics/webots/R2023b/projects/robots/surveyor/protos/textures/surveyor_serial_roughness.jpg"
                          ]
                        }
                        metalness 0
                        metalnessMap ImageTexture {
                          url [
                            "https://raw.githubusercontent.com/cyberbotics/webots/R2023b/projects/robots/surveyor/protos/textures/surveyor_serial_metalness.jpg"
                          ]
                        }
                        normalMap ImageTexture {
                          url [
                            "https://raw.githubusercontent.com/cyberbotics/webots/R2023b/projects/robots/surveyor/protos/textures/surveyor_serial_normal.jpg"
                          ]
                        }
                      }
                      geometry IndexedFaceSet {
                        coord Coordinate {
                          point [
                            -0.0184 -0.01 0.00151
                            -0.0183 0.01 0.00151
                            0.0185 0.01 0.00151
                            0.0185 -0.01 0.00151
                          ]
                        }
                        texCoord TextureCoordinate {
                          point [
                            0 0
                            1 0
                            1 1
                            0 1
                          ]
                        }
                        coordIndex [
                          0, 3, 2, 1, -1
                        ]
                        texCoordIndex [
                          0, 1, 2, 3, -1
                        ]
                      }
                    }
                    Shape {
                      appearance USE BLACK
                      geometry Box {
                        size 0.037 0.02 0.003
                      }
                    }
                  ]
                }
              ]
            }
            DEF SUPPORT Group {
              children [
                Pose {
                  translation -0.0364 0 -0.004
                  children [
                    Shape {
                      appearance DEF BlackRobotAlphie PBRAppearance {
                        baseColor 0 0 0
                        roughness 1
                        metalness 0
                        name ""
                      }
                      geometry Box {
                        size 0.04 0.0525 0.0011
                      }
                    }
                  ]
                  translationStep 0.001
                }
                Pose {
                  translation -0.0433 0 0.0102
                  children [
                    Shape {
                      appearance DEF BlackRobotAlphie PBRAppearance {
                        baseColor 0 0 0
                        roughness 1
                        metalness 0
                        name ""
                      }
                      geometry Box {
                        size 0.03 0.0525 0.0011
                      }
                    }
                  ]
                  translationStep 0.0001
                }
                Shape {
                  appearance PBRAppearance {
                    baseColor 0.85098 0.85098 0.85098
                    baseColorMap ImageTexture {
                      url [
                        "../pictures/FrontAlphie.png"
                      ]
                      repeatS FALSE
                      repeatT FALSE
                    }
                    roughness 1
                    roughnessMap ImageTexture {
                      url [
                        "https://raw.githubusercontent.com/cyberbotics/webots/R2023b/projects/robots/surveyor/protos/textures/surveyor_top_roughness.jpg"
                      ]
                    }
                    metalness 0
                    metalnessMap ImageTexture {
                      url [
                        "https://raw.githubusercontent.com/cyberbotics/webots/R2023b/projects/robots/surveyor/protos/textures/surveyor_top_metalness.jpg"
                      ]
                    }
                    normalMap ImageTexture {
                      url [
                        "https://raw.githubusercontent.com/cyberbotics/webots/R2023b/projects/robots/surveyor/protos/textures/surveyor_top_normal.jpg"
                      ]
                    }
                  }
                  geometry IndexedFaceSet {
                    coord Coordinate {
                      point [
                        -0.059 0.026 0.011
                        -0.028 0.026 0.011
                        -0.028 -0.026 0.011
                        -0.059 -0.026 0.011
                      ]
                    }
                    texCoord TextureCoordinate {
                      point [
                        0 0
                        1 0
                        1 1
                        0 1
                      ]
                    }
                    coordIndex [
                      0, 3, 2, 1, -1
                    ]
                    texCoordIndex [
                      0, 1, 2, 3, -1
                    ]
                  }
                }
                Pose {
                  translation -0.0227073 3.05188e-07 0.00330141
                  rotation -0.6848107156457631 0.6848157156436869 -0.2491218965570118 2.65328
                  children [
                    Shape {
                      appearance USE BlackRobotAlphie
                      geometry Box {
                        size 0.0525 0.0012 0.0185
                      }
                    }
                  ]
                  translationStep 0.0001
                }
              ]
            }
          ]
        }
        DEF TOP_PLATE Group {
          children [
            Pose {
              translation -0.0186 0 0.0449
              children [
                Shape {
                  appearance PBRAppearance {
                    baseColor 0 0 0
                    roughness 1
                    metalness 0
                  }
                  geometry Box {
                    size 0.076 0.053 0.0015
                  }
                }
              ]
              translationStep 0.001
            }
            DEF TOP Pose {
              translation -0.006 -6.36861e-08 0.0477
              rotation 0 0 1 3.14159
              children [
                GPS {
                  rotation 0 0 1 3.14159
                }
                Compass {
                  rotation 0 0 1 3.14159
                }
                Shape {
                  appearance PBRAppearance {
                    baseColorMap ImageTexture {
                      url [
                        "../pictures/TopAlphie.png"
                      ]
                      repeatS FALSE
                      repeatT FALSE
                    }
                    roughness 1
                    roughnessMap ImageTexture {
                      url [
                        "https://raw.githubusercontent.com/cyberbotics/webots/R2023b/projects/robots/surveyor/protos/textures/surveyor_top_roughness.jpg"
                      ]
                    }
                    metalness 0
                    metalnessMap ImageTexture {
                      url [
                        "https://raw.githubusercontent.com/cyberbotics/webots/R2023b/projects/robots/surveyor/protos/textures/surveyor_top_metalness.jpg"
                      ]
                    }
                    normalMap ImageTexture {
                      url [
                        "https://raw.githubusercontent.com/cyberbotics/webots/R2023b/projects/robots/surveyor/protos/textures/surveyor_top_normal.jpg"
                      ]
                    }
                  }
                  geometry IndexedFaceSet {
                    coord Coordinate {
                      point [
                        0.05 -0.027 -0.002
                        -0.026 -0.027 -0.002
                        -0.026 0.027 -0.002
                        0.05 0.027 -0.002
                      ]
                    }
                    texCoord TextureCoordinate {
                      point [
                        0 0
                        1 0
                        1 1
                        0 1
                      ]
                    }
                    coordIndex [
                      0, 3, 2, 1, -1
                    ]
                    texCoordIndex [
                      0, 1, 2, 3, -1
                    ]
                  }
                }
              ]
              translationStep 0.001
            }
          ]
        }
        DEF BATTERIES Group {
          children [
            Pose {
              translation -0.0220079 -5.51926e-08 0.0270237
              rotation 0.577656895078166 -0.5771968951617173 0.5771968951617173 2.09394
              children [
                DEF BATTERY Shape {
                  appearance DEF BlackRobot PBRAppearance {
                    baseColor 0.360784 0.360784 0.360784
                    roughness 1
                    metalness 0
                  }
                  geometry Box {
                    size 0.015 0.02 0.05
                  }
                }
              ]
            }
          ]
        }
      ]
    }
    DEF ANTENNA_EMITTER Emitter {
      translation 0.0451 0.0118 0.037
      children [
        DEF RangeEmitter Shape {
          appearance PBRAppearance {
            baseColor 1 1 0
            transparency 0.8
            roughness 1
            metalness 0
          }
          geometry Sphere {
            radius 1.5
            subdivision 5
          }
        }
        Pose {
          translation 0 0 -0.008
          children [
            Shape {
              appearance USE BLACK
              geometry Cylinder {
                height 0.019
                radius 0.0006
              }
            }
          ]
        }
        Pose {
          children [
            Shape {
              appearance USE BLACK
              geometry Cylinder {
                height 0.007
                radius 0.0015
              }
            }
          ]
        }
      ]
      translationStep 0.0001
      range 1.5
    }
    DEF ANTENNA_RECEIVER Receiver {
      translation 0.0451 0.0118 0.037
    }
    DEF FIRST_LEFT_WHEEL HingeJoint {
      jointParameters HingeJointParameters {
        position -10760.808663440519
        axis 0 -1 0
        anchor 0.049 0.0394 0.014
      }
      device [
        RotationalMotor {
          name "wheel_motor00"
          maxVelocity 50
        }
        PositionSensor {
          name "wheel_sensor00"
        }
      ]
      endPoint Solid {
        translation 0.049 0.0394 0.014
        rotation 0 1 0 3.995417549066964
        name "first left wheel"
        contactMaterial "wheel"
        boundingObject DEF BOUNDING_WHEEL Pose {
          rotation 1 0 0 -1.57
          children [
            Cylinder {
              height 0.0198
              radius 0.014
            }
          ]
        }
        physics DEF PHYSICS_FRONT_WHEEL Physics {
          density -1
          mass 0.005
        }
      }
    }
    DEF SECOND_LEFT_WHEEL HingeJoint {
      jointParameters HingeJointParameters {
        position -8811.973257582345
        axis 0 -1 0
        anchor 0.0245 0.0394 0.014
      }
      device [
        RotationalMotor {
          name "wheel_motor01"
          maxVelocity 50
        }
        PositionSensor {
          name "wheel_sensor01"
        }
      ]
      endPoint Solid {
        translation 0.0245 0.0394 0.014
        rotation 0 0.9999999999999999 0 2.9474569165652276
        name "second left wheel"
        contactMaterial "wheel"
        boundingObject USE BOUNDING_WHEEL
        physics USE PHYSICS_FRONT_WHEEL
      }
    }
    DEF THIRD_LEFT_WHEEL HingeJoint {
      jointParameters HingeJointParameters {
        position -10733.770071571129
        axis 0 -1 0
        anchor 0 0.0394 0.014
      }
      device [
        RotationalMotor {
          name "wheel_motor02"
          maxVelocity 50
        }
        PositionSensor {
          name "wheel_sensor02"
        }
      ]
      endPoint Solid {
        translation 0 0.0394 0.014
        rotation 0 1 0 2.089566908395235
        name "third left wheel"
        contactMaterial "center_wheel"
        boundingObject USE BOUNDING_WHEEL
        physics DEF PHYSICS_CENTER_WHEEL Physics {
          density -1
          mass 0.005
        }
      }
    }
    DEF FOURTH_LEFT_WHEEL HingeJoint {
      jointParameters HingeJointParameters {
        position -10733.770078920583
        axis 0 -1 0
        anchor -0.0245 0.0394 0.014
      }
      device [
        RotationalMotor {
          name "wheel_motor03"
          maxVelocity 50
        }
        PositionSensor {
          name "wheel_sensor03"
        }
      ]
      endPoint Solid {
        translation -0.0245 0.0394 0.014
        rotation 0 1 0 2.089574257849116
        name "fourth left wheel"
        contactMaterial "wheel"
        boundingObject USE BOUNDING_WHEEL
        physics USE PHYSICS_FRONT_WHEEL
      }
    }
    DEF LAST_LEFT_WHEEL HingeJoint {
      jointParameters HingeJointParameters {
        position -10733.77006883378
        axis 0 -1 0
        anchor -0.049 0.0394 0.014
      }
      device [
        RotationalMotor {
          name "wheel_motor04"
          maxVelocity 50
        }
        PositionSensor {
          name "wheel_sensor04"
        }
      ]
      endPoint Solid {
        translation -0.049 0.0394 0.014
        rotation 0 1 0 2.0895641710471944
        name "last left wheel"
        contactMaterial "wheel"
        boundingObject USE BOUNDING_WHEEL
        physics USE PHYSICS_FRONT_WHEEL
      }
    }
    DEF FIRST_RIGHT_WHEEL HingeJoint {
      jointParameters HingeJointParameters {
        position -9592.632183864045
        axis 0 -1 0
        anchor 0.049 -0.0394 0.014
      }
      device [
        RotationalMotor {
          name "wheel_motor05"
          maxVelocity 50
        }
        PositionSensor {
          name "wheel_sensor05"
        }
      ]
      endPoint Solid {
        translation 0.049 -0.0394 0.014
        rotation 0 1 0 4.491405107996182
        name "first right wheel"
        contactMaterial "wheel"
        boundingObject USE BOUNDING_WHEEL
        physics USE PHYSICS_FRONT_WHEEL
      }
    }
    DEF SECOND_RIGHT_WHEEL HingeJoint {
      jointParameters HingeJointParameters {
        position -9592.632181505915
        axis 0 -1 0
        anchor 0.0245 -0.0394 0.014
      }
      device [
        RotationalMotor {
          name "wheel_motor06"
          maxVelocity 50
        }
        PositionSensor {
          name "wheel_sensor06"
        }
      ]
      endPoint Solid {
        translation 0.0245 -0.0394 0.014
        rotation 0 1 0 4.491402749865595
        name "second right wheel"
        contactMaterial "wheel"
        boundingObject USE BOUNDING_WHEEL
        physics USE PHYSICS_FRONT_WHEEL
      }
    }
    DEF THIRD_RIGHT_WHEEL HingeJoint {
      jointParameters HingeJointParameters {
        position -9592.632188469672
        axis 0 -1 0
        anchor 0 -0.0394 0.014
      }
      device [
        RotationalMotor {
          name "wheel_motor07"
          maxVelocity 50
        }
        PositionSensor {
          name "wheel_sensor07"
        }
      ]
      endPoint Solid {
        translation 0 -0.0394 0.014
        rotation 0 1 0 4.491409713622782
        name "third right wheel"
        contactMaterial "center_wheel"
        boundingObject USE BOUNDING_WHEEL
        physics USE PHYSICS_CENTER_WHEEL
      }
    }
    DEF FOURTH_RIGHT_WHEEL HingeJoint {
      jointParameters HingeJointParameters {
        position -9592.632198916926
        axis 0 -1 0
        anchor -0.0245 -0.0394 0.014
      }
      device [
        RotationalMotor {
          name "wheel_motor08"
          maxVelocity 50
        }
        PositionSensor {
          name "wheel_sensor08"
        }
      ]
      endPoint Solid {
        translation -0.0245 -0.0394 0.014
        rotation 0 0.9999999999999999 0 4.491420160877463
        name "forth right wheel"
        contactMaterial "wheel"
        boundingObject USE BOUNDING_WHEEL
        physics USE PHYSICS_FRONT_WHEEL
      }
    }
    DEF LAST_RIGHT_WHEEL HingeJoint {
      jointParameters HingeJointParameters {
        position -9592.632194539383
        axis 0 -1 0
        anchor -0.049 -0.0394 0.014
      }
      device [
        RotationalMotor {
          name "wheel_motor09"
          maxVelocity 50
        }
        PositionSensor {
          name "wheel_sensor09"
        }
      ]
      endPoint Solid {
        translation -0.049 -0.0394 0.014
        rotation 0 1 0 4.491415783333944
        name "last right wheel"
        contactMaterial "wheel"
        boundingObject USE BOUNDING_WHEEL
        physics USE PHYSICS_FRONT_WHEEL
      }
    }
  ]
  name "Alphie(3)"
  model "Alphie'sModel"
  description "Simulation of the real robot Alphie"
  boundingObject Group {
    children [
      Pose {
        translation 0 0 0.04
        children [
          Box {
            size 0.125 0.1 0.07
          }
        ]
      }
    ]
  }
  physics Physics {
    density -1
    mass 0.324
    centerOfMass [
      -0.005 0 0.028
    ]
    inertiaMatrix [
      0.000267079 0.000473553 0.000418585
      0 -6.02166e-06 0
    ]
  }
  controller "MainController"
}
